Workbook

Sheet Balance Sheet - COL
A1: Balance Sheet | F1: Trend Analysis | G1: Horiztonal Analysis | K1: Vertical Analysis
A2: Coles Group Limited
B3: 2021 | C3: 2022 | D3: 2023 | E3: 2024 | F3: 2021-2024 | G3: 2023 $Change | H3: 2023 % Change | I3: 2024 $ Change | J3: 2024 % Change | K3: 2023 | L3: 2024
A5: Current Assets
A6: Cash and Cash Equivalents | B6: 787000000 | C6: 589000000 | D6: 597000000 | E6: 675000000 | G6: =D6-C6 -> 8000000 | H6: =(D6-C6)/C6 -> 0.013582343 | I6: =E6-D6 -> 78000000 | J6: =(E6-D6)/D6 -> 0.13065327 | K6: =D6/($D$12+$D$21) -> 0.032637218 | L6: =E6/($E$12+$E$21) -> 0.03397081
A7: Trade and other receivables | B7: 368000000 | C7: 470000000 | D7: 605000000 | E7: 496000000 | G7: =D7-C7 -> 135000000 | H7: =(D7-C7)/C7 -> 0.28723404 | I7: =E7-D7 -> -109000000 | J7: =(E7-D7)/D7 -> -0.18016529 | K7: =D7/($D$12+$D$21) -> 0.033074568 | L7: =E7/($E$12+$E$21) -> 0.024962255
A8: Prepaid Expenses | B8: 85000000 | C8: 83000000 | D8: 82000000 | E8: 102000000 | G8: =D8-C8 -> -1000000 | H8: =(D8-C8)/C8 -> -0.012048193 | I8: =E8-D8 -> 20000000 | J8: =(E8-D8)/D8 -> 0.24390244 | K8: =D8/($D$12+$D$21) -> 0.004482834 | L8: =E8/($E$12+$E$21) -> 0.0051333669
A9: Inventories | B9: 2107000000 | C9: 2448000000 | D9: 2323000000 | E9: 2703000000 | G9: =D9-C9 -> -125000000 | H9: =(D9-C9)/C9 -> -0.051062092 | I9: =E9-D9 -> 380000000 | J9: =(E9-D9)/D9 -> 0.16358158 | K9: =D9/($D$12+$D$21) -> 0.12699541 | L9: =E9/($E$12+$E$21) -> 0.13603422
A10: Assets Held for Sale | B10: 85000000 | C10: 82000000 | D10: 127000000 | E10: 3000000 | G10: =D10-C10 -> 45000000 | H10: =(D10-C10)/C10 -> 0.54878049 | I10: =E10-D10 -> -124000000 | J10: =(E10-D10)/D10 -> -0.97637795 | K10: =D10/($D$12+$D$21) -> 0.0069429259 | L10: =E10/($E$12+$E$21) -> 0.00015098138
A11: Other Assets | B11: 2000000 | C11: 79000000 | D11: 18000000 | E11: 7000000 | G11: =D11-C11 -> -61000000 | H11: =(D11-C11)/C11 -> -0.7721519 | I11: =E11-D11 -> -11000000 | J11: =(E11-D11)/D11 -> -0.61111111 | K11: =D11/($D$12+$D$21) -> 0.00098403674 | L11: =E11/($E$12+$E$21) -> 0.00035228988
A12: Total Current Assets | B12: =SUM(B6:B11) -> 3434000000 | C12: =SUM(C6:C11) -> 3751000000 | D12: =SUM(D6:D11) -> 3752000000 | E12: =SUM(E6:E11) -> 3986000000 | G12: =D12-C12 -> 1000000 | H12: =(D12-C12)/C12 -> 0.00026659557 | I12: =E12-D12 -> 234000000 | J12: =(E12-D12)/D12 -> 0.062366738 | K12: =D12/($D$12+$D$21) -> 0.20511699 | L12: =E12/($E$12+$E$21) -> 0.20060393
A14: Non-Current Assets
A15: Investments | B15: 220000000 | C15: 219000000 | D15: 220000000 | E15: 225000000 | G15: =D15-C15 -> 1000000 | H15: =(D15-C15)/C15 -> 0.00456621 | I15: =E15-D15 -> 5000000 | J15: =(E15-D15)/D15 -> 0.022727273 | K15: =D15/($D$12+$D$21) -> 0.012027116 | L15: =E15/($E$12+$E$21) -> 0.011323603
A16: Property, plant and equipment | B16: 11751000000 | C16: 12006000000 | D16: 11492000000 | E16: 12667000000 | G16: =D16-C16 -> -514000000 | H16: =(D16-C16)/C16 -> -0.042811927 | I16: =E16-D16 -> 1175000000 | J16: =(E16-D16)/D16 -> 0.10224504 | K16: =D16/($D$12+$D$21) -> 0.62825279 | L16: =E16/($E$12+$E$21) -> 0.63749371
A17: Intangible Assets | B17: 542000000 | C17: 704000000 | D17: 920000000 | E17: 1052000000 | G17: =D17-C17 -> 216000000 | H17: =(D17-C17)/C17 -> 0.30681818 | I17: =E17-D17 -> 132000000 | J17: =(E17-D17)/D17 -> 0.14347826 | K17: =D17/($D$12+$D$21) -> 0.050295211 | L17: =E17/($E$12+$E$21) -> 0.052944137
A18: Goodwill | B18: 1156000000 | C18: 1160000000 | D18: 1115000000 | E18: 1151000000 | G18: =D18-C18 -> -45000000 | H18: =(D18-C18)/C18 -> -0.038793103 | I18: =E18-D18 -> 36000000 | J18: =(E18-D18)/D18 -> 0.032286996 | K18: =D18/($D$12+$D$21) -> 0.060955609 | L18: =E18/($E$12+$E$21) -> 0.057926522
A19: Future Tax Benefit | B19: 873000000 | C19: 822000000 | D19: 740000000 | E19: 717000000 | G19: =D19-C19 -> -82000000 | H19: =(D19-C19)/C19 -> -0.099756691 | I19: =E19-D19 -> -23000000 | J19: =(E19-D19)/D19 -> -0.031081081 | K19: =D19/($D$12+$D$21) -> 0.040454844 | L19: =E19/($E$12+$E$21) -> 0.03608455
A20: Other | B20: 147000000 | C20: 174000000 | D20: 53000000 | E20: 72000000 | G20: =D20-C20 -> -121000000 | H20: =(D20-C20)/C20 -> -0.6954023 | I20: =E20-D20 -> 19000000 | J20: =(E20-D20)/D20 -> 0.35849057 | K20: =D20/($D$12+$D$21) -> 0.0028974415 | L20: =E20/($E$12+$E$21) -> 0.0036235531
A21: Total Non-Current Assets | B21: =SUM(B15:B20) -> 14689000000 | C21: =SUM(C15:C20) -> 15085000000 | D21: =SUM(D15:D20) -> 14540000000 | E21: =SUM(E15:E20) -> 15884000000 | G21: =D21-C21 -> -545000000 | H21: =(D21-C21)/C21 -> -0.036128605 | I21: =E21-D21 -> 1344000000 | J21: =(E21-D21)/D21 -> 0.092434663 | K21: =D21/($D$12+$D$21) -> 0.79488301 | L21: =E21/($E$12+$E$21) -> 0.79939607
K22: =D22/($D$12+$D$21) -> 0 | L22: =E22/($E$12+$E$21) -> 0
A23: Total Assets | B23: =B21+B12 -> 18123000000 | C23: =C21+C12 -> 18836000000 | D23: =D21+D12 -> 18292000000 | E23: =E21+E12 -> 19870000000 | G23: =D23-C23 -> -544000000 | H23: =(D23-C23)/C23 -> -0.028880866 | I23: =E23-D23 -> 1578000000 | J23: =(E23-D23)/D23 -> 0.086267221 | K23: =D23/($D$12+$D$21) -> 1 | L23: =E23/($E$12+$E$21) -> 1
A25: Current Liabilities
A26: Account Payable | B26: 3660000000 | C26: 4335000000 | D26: 4434000000 | E26: 4584000000 | G26: =D26-C26 -> 99000000 | H26: =(D26-C26)/C26 -> 0.02283737 | I26: =E26-D26 -> 150000000 | J26: =(E26-D26)/D26 -> 0.033829499 | K26: =D26/($D$30+$D$38) -> 0.20773988 | L26: =E26/($E$30+$E$36) -> 0.28204024
A27: Short-Term Debt | B27: 897000000 | C27: 914000000 | D27: 820000000 | E27: 911000000 | G27: =D27-C27 -> -94000000 | H27: =(D27-C27)/C27 -> -0.10284464 | I27: =E27-D27 -> 91000000 | J27: =(E27-D27)/D27 -> 0.11097561 | K27: =D27/($D$30+$D$38) -> 0.038418291 | L27: =E27/($E$30+$E$36) -> 0.056051191
A28: Provisions | B28: 1010000000 | C28: 854000000 | D28: 905000000 | E28: 1016000000 | G28: =D28-C28 -> 51000000 | H28: =(D28-C28)/C28 -> 0.05971897 | I28: =E28-D28 -> 111000000 | J28: =(E28-D28)/D28 -> 0.12265193 | K28: =D28/($D$30+$D$38) -> 0.042400675 | L28: =E28/($E$30+$E$36) -> 0.062511536
A29: Other | B29: 252000000 | C29: 312000000 | D29: 249000000 | E29: 260000000 | G29: =D29-C29 -> -63000000 | H29: =(D29-C29)/C29 -> -0.20192308 | I29: =E29-D29 -> 11000000 | J29: =(E29-D29)/D29 -> 0.044176707 | K29: =D29/($D$30+$D$38) -> 0.011666042 | L29: =E29/($E$30+$E$36) -> 0.015997047
A30: Total Current Liabilities | B30: =SUM(B26:B29) -> 5819000000 | C30: =SUM(C26:C29) -> 6415000000 | D30: =SUM(D26:D29) -> 6408000000 | E30: =SUM(E26:E29) -> 6771000000 | G30: =D30-C30 -> -7000000 | H30: =(D30-C30)/C30 -> -0.0010911925 | I30: =E30-D30 -> 363000000 | J30: =(E30-D30)/D30 -> 0.05664794 | K30: =D30/($D$30+$D$38) -> 0.30022489 | L30: =E30/(E38) -> 0.41660001
A32: Non-Current Liabilities
A33: Long-Term Debt | B33: 9001000000 | C33: 8862000000 | D33: 8147000000 | E33: 9158000000 | G33: =D33-C33 -> -715000000 | H33: =(D33-C33)/C33 -> -0.080681562 | I33: =E33-D33 -> 1011000000 | J33: =(E33-D33)/D33 -> 0.12409476 | K33: =D33/($D$30+$D$36) -> 0.54546063 | L33: =E33/($E$30+$E$36) -> 0.56346521
A34: Provisions | B34: 458000000 | C34: 424000000 | D34: 376000000 | E34: 323000000 | G34: =D34-C34 -> -48000000 | H34: =(D34-C34)/C34 -> -0.11320755 | I34: =E34-D34 -> -53000000 | J34: =(E34-D34)/D34 -> -0.14095745 | K34: =D34/($D$30+$D$36) -> 0.025174076 | L34: =E34/($E$30+$E$36) -> 0.019873254
A35: Other | B35: 32000000 | C35: 11000000 | D35: 5000000 | E35: 1000000 | G35: =D35-C35 -> -6000000 | H35: =(D35-C35)/C35 -> -0.54545455 | I35: =E35-D35 -> -4000000 | J35: =(E35-D35)/D35 -> -0.8 | K35: =D35/($D$30+$D$36) -> 0.00033476165 | L35: =E35/($E$30+$E$36) -> 6.1527103e-05
A36: Total Non-Current Liabilities | B36: =SUM(B33:B35) -> 9491000000 | C36: =SUM(C33:C35) -> 9297000000 | D36: =SUM(D33:D35) -> 8528000000 | E36: =SUM(E33:E35) -> 9482000000 | G36: =D36-C36 -> -769000000 | H36: =(D36-C36)/C36 -> -0.082714854 | I36: =E36-D36 -> 954000000 | J36: =(E36-D36)/D36 -> 0.11186679 | K36: =D36/($D$30+$D$36) -> 0.57096947 | L36: =E36/($E$30+$E$36) -> 0.58339999
A38: Total Liabilities | B38: =B36+B30 -> 15310000000 | C38: =C36+C30 -> 15712000000 | D38: =D36+D30 -> 14936000000 | E38: =E36+E30 -> 16253000000 | G38: =D38-C38 -> -776000000 | H38: =(D38-C38)/C38 -> -0.049389002 | I38: =E38-D38 -> 1317000000 | J38: =(E38-D38)/D38 -> 0.088176219 | K38: =D38/($D$30+$D$36) -> 1 | L38: =E38/($E$30+$E$36) -> 1
A40: Equity
A41: Share Capital | B41: 1585000000 | C41: 1636000000 | D41: 1644000000 | E41: 1672000000 | G41: =D41-C41 -> 8000000 | H41: =(D41-C41)/C41 -> 0.0048899756 | I41: =E41-D41 -> 28000000 | J41: =(E41-D41)/D41 -> 0.01703163 | K41: =D41/($D$44) -> 0.48986889 | L41: =E41/($E$44) -> 0.46226154
A42: Reserves | B42: 69000000 | C42: 95000000 | D42: 104000000 | E42: 103000000 | G42: =D42-C42 -> 9000000 | H42: =(D42-C42)/C42 -> 0.094736842 | I42: =E42-D42 -> -1000000 | J42: =(E42-D42)/D42 -> -0.0096153846 | K42: =D42/($D$44) -> 0.030989273 | L42: =E42/($E$44) -> 0.028476638
A43: Retained Earnings | B43: 1159000000 | C43: 1393000000 | D43: 1608000000 | E43: 1842000000 | G43: =D43-C43 -> 215000000 | H43: =(D43-C43)/C43 -> 0.15434314 | I43: =E43-D43 -> 234000000 | J43: =(E43-D43)/D43 -> 0.14552239 | K43: =D43/($D$44) -> 0.47914184 | L43: =E43/($E$44) -> 0.50926182
A44: Total Equity | B44: =SUM(B41:B43) -> 2813000000 | C44: =SUM(C41:C43) -> 3124000000 | D44: =SUM(D41:D43) -> 3356000000 | E44: =SUM(E41:E43) -> 3617000000 | G44: =D44-C44 -> 232000000 | H44: =(D44-C44)/C44 -> 0.074263764 | I44: =E44-D44 -> 261000000 | J44: =(E44-D44)/D44 -> 0.077771156 | K44: =D44/($D$44) -> 1 | L44: =E44/($E$44) -> 1
A46: CHECK EQUITY | B46: =B23-B38 -> 2813000000 | C46: =C23-C38 -> 3124000000 | D46: =D23-D38 -> 3356000000 | E46: =E23-E38 -> 3617000000 | G46: =D46-C46 -> 232000000 | H46: =(D46-C46)/C46 -> 0.074263764 | I46: =E46-D46 -> 261000000 | J46: =(E46-D46)/D46 -> 0.077771156 | K46: =D46/($D$12+$D$21) -> 0.18346818 | L46: =E46/($E$12+$E$21) -> 0.18203322

Sheet Balance Sheet - WOW
A1: Balance Sheet | F1: Trend Analysis | G1: Horiztonal Analysis | K1: Vertical Analysis
A2: Woolworths Group Limited
B3: 2021 | C3: 2022 | D3: 2023 | E3: 2024 | F3: 2021-2024 | G3: 2023 $Change | H3: 2023 % Change | I3: 2024 $ Change | J3: 2024 % Change | K3: 2023 | L3: 2024
A5: Current Assets
A6: Cash and Cash Equivalents | B6: 1009000000 | C6: 1032000000 | D6: 1135000000 | E6: 1298000000 | G6: =D6-C6 -> 103000000 | H6: =(D6-C6)/C6 -> 0.099806202 | I6: =E6-D6 -> 163000000 | J6: =(E6-D6)/D6 -> 0.14361233 | K6: =D6/($D$13+$D$23) -> 0.033731574 | L6: =E6/($E$13+$E$23) -> 0.038248468
A7: Trade and other receivables | B7: 480000000 | C7: 856000000 | D7: 1016000000 | E7: 1106000000 | G7: =D7-C7 -> 160000000 | H7: =(D7-C7)/C7 -> 0.18691589 | I7: =E7-D7 -> 90000000 | J7: =(E7-D7)/D7 -> 0.088582677 | K7: =D7/($D$13+$D$23) -> 0.03019496 | L7: =E7/($E$13+$E$23) -> 0.032590759
A8: Prepaid Expenses | B8: 169000000 | C8: 188000000 | D8: 0 | E8: 156000000 | G8: =D8-C8 -> -188000000 | H8: =(D8-C8)/C8 -> -1 | I8: =E8-D8 -> 156000000 | J8: 0 | K8: =D8/($D$13+$D$23) -> 0 | L8: =E8/($E$13+$E$23) -> 0.0045968883
A9: Inventories | B9: 3132000000 | C9: 3593000000 | D9: 3698000000 | E9: 4187000000 | G9: =D9-C9 -> 105000000 | H9: =(D9-C9)/C9 -> 0.02922349 | I9: =E9-D9 -> 489000000 | J9: =(E9-D9)/D9 -> 0.13223364 | K9: =D9/($D$13+$D$23) -> 0.10990252 | L9: =E9/($E$13+$E$23) -> 0.1233793
A10: Investments | B10: 19000000 | C10: 106000000 | D10: 51000000 | E10: 23000000 | G10: =D10-C10 -> -55000000 | H10: =(D10-C10)/C10 -> -0.51886792 | I10: =E10-D10 -> -28000000 | J10: =(E10-D10)/D10 -> -0.54901961 | K10: =D10/($D$13+$D$23) -> 0.0015156919 | L10: =E10/($E$13+$E$23) -> 0.00067774635
A11: Assests Held for Sale | B11: 10959000000 | C11: 287000000 | D11: 225000000 | E11: 200000000 | G11: =D11-C11 -> -62000000 | H11: =(D11-C11)/C11 -> -0.21602787 | I11: =E11-D11 -> -25000000 | J11: =(E11-D11)/D11 -> -0.11111111 | K11: =D11/($D$13+$D$23) -> 0.0066868759 | L11: =E11/($E$13+$E$23) -> 0.0058934465
A12: Other Assets | B12: 18000000 | C12: 48000000 | D12: 250000000 | E12: 21000000 | G12: =D12-C12 -> 202000000 | H12: =(D12-C12)/C12 -> 4.2083333 | I12: =E12-D12 -> -229000000 | J12: =(E12-D12)/D12 -> -0.916 | K12: =D12/($D$13+$D$23) -> 0.0074298621 | L12: =E12/($E$13+$E$23) -> 0.00061881188
A13: Total Current Assets | B13: =SUM(B6:B12) -> 15786000000 | C13: =SUM(C6:C12) -> 6110000000 | D13: =SUM(D6:D12) -> 6375000000 | E13: =SUM(E6:E12) -> 6991000000 | G13: =D13-C13 -> 265000000 | H13: =(D13-C13)/C13 -> 0.043371522 | I13: =E13-D13 -> 616000000 | J13: =(E13-D13)/D13 -> 0.096627451 | K13: =D13/($D$13+$D$23) -> 0.18946148 | L13: =E13/($E$13+$E$23) -> 0.20600542
A15: Non-Current Assets
A16: Receivables | B16: 136000000 | C16: 159000000 | D16: 142000000 | E16: 454000000 | G16: =D16-C16 -> -17000000 | H16: =(D16-C16)/C16 -> -0.10691824 | I16: =E16-D16 -> 312000000 | J16: =(E16-D16)/D16 -> 2.1971831 | K16: =D16/($D$13+$D$23) -> 0.0042201617 | L16: =E16/($E$13+$E$23) -> 0.013378124
A17: Investments | B17: 132000000 | C17: 1786000000 | D17: 1263000000 | E17: 678000000 | G17: =D17-C17 -> -523000000 | H17: =(D17-C17)/C17 -> -0.29283315 | I17: =E17-D17 -> -585000000 | J17: =(E17-D17)/D17 -> -0.4631829 | K17: =D17/($D$13+$D$23) -> 0.037535663 | L17: =E17/($E$13+$E$23) -> 0.019978784
A18: Property, plant and equipment | B18: 17030000000 | C18: 18226000000 | D18: 18348000000 | E18: 19282000000 | G18: =D18-C18 -> 122000000 | H18: =(D18-C18)/C18 -> 0.0066937342 | I18: =E18-D18 -> 934000000 | J18: =(E18-D18)/D18 -> 0.050904731 | K18: =D18/($D$13+$D$23) -> 0.54529244 | L18: =E18/($E$13+$E$23) -> 0.56818718
A19: Intangible Assets | B19: 1790000000 | C19: 2080000000 | D19: 2189000000 | E19: 2407000000 | G19: =D19-C19 -> 109000000 | H19: =(D19-C19)/C19 -> 0.052403846 | I19: =E19-D19 -> 218000000 | J19: =(E19-D19)/D19 -> 0.099588853 | K19: =D19/($D$13+$D$23) -> 0.065055873 | L19: =E19/($E$13+$E$23) -> 0.070927628
A20: Goodwill | B20: 2881000000 | C20: 3198000000 | D20: 3504000000 | E20: 2466000000 | G20: =D20-C20 -> 306000000 | H20: =(D20-C20)/C20 -> 0.095684803 | I20: =E20-D20 -> -1038000000 | J20: =(E20-D20)/D20 -> -0.29623288 | K20: =D20/($D$13+$D$23) -> 0.10413695 | L20: =E20/($E$13+$E$23) -> 0.072666195
A21: Future Tax Benefit | B21: 1371000000 | C21: 1337000000 | D21: 1478000000 | E21: 1647000000 | G21: =D21-C21 -> 141000000 | H21: =(D21-C21)/C21 -> 0.10545999 | I21: =E21-D21 -> 169000000 | J21: =(E21-D21)/D21 -> 0.11434371 | K21: =D21/($D$13+$D$23) -> 0.043925345 | L21: =E21/($E$13+$E$23) -> 0.048532532
A22: Other | B22: 110000000 | C22: 377000000 | D22: 349000000 | E22: 11000000 | G22: =D22-C22 -> -28000000 | H22: =(D22-C22)/C22 -> -0.074270557 | I22: =E22-D22 -> -338000000 | J22: =(E22-D22)/D22 -> -0.96848138 | K22: =D22/($D$13+$D$23) -> 0.010372087 | L22: =E22/($E$13+$E$23) -> 0.00032413956
A23: Total Non-Current Assets | B23: =SUM(B16:B22) -> 23450000000 | C23: =SUM(C16:C22) -> 27163000000 | D23: =SUM(D16:D22) -> 27273000000 | E23: =SUM(E16:E22) -> 26945000000 | G23: =D23-C23 -> 110000000 | H23: =(D23-C23)/C23 -> 0.0040496263 | I23: =E23-D23 -> -328000000 | J23: =(E23-D23)/D23 -> -0.012026546 | K23: =D23/($D$13+$D$23) -> 0.81053852 | L23: =E23/($E$13+$E$23) -> 0.79399458
K24: =D24/($D$13+$D$23) -> 0 | L24: =E24/($E$13+$E$23) -> 0
A25: Total Assets | B25: =B23+B13 -> 39236000000 | C25: =C23+C13 -> 33273000000 | D25: =D23+D13 -> 33648000000 | E25: =E23+E13 -> 33936000000 | G25: =D25-C25 -> 375000000 | H25: =(D25-C25)/C25 -> 0.011270399 | I25: =E25-D25 -> 288000000 | J25: =(E25-D25)/D25 -> 0.0085592011 | K25: =D25/($D$13+$D$23) -> 1 | L25: =E25/($E$13+$E$23) -> 1
A27: Current Liabilities
A28: Account Payable | B28: 6467000000 | C28: 7002000000 | D28: 7623000000 | E28: 7762000000 | G28: =D28-C28 -> 621000000 | H28: =(D28-C28)/C28 -> 0.088688946 | I28: =E28-D28 -> 139000000 | J28: =(E28-D28)/D28 -> 0.018234291 | K28: =D28/($D$32+$D$40) -> 0.19561703 | L28: =E28/($E$32+$E$38) -> 0.27363745
A29: Short-Term Debt | B29: 1614000000 | C29: 1926000000 | D29: 2103000000 | E29: 2311000000 | G29: =D29-C29 -> 177000000 | H29: =(D29-C29)/C29 -> 0.091900312 | I29: =E29-D29 -> 208000000 | J29: =(E29-D29)/D29 -> 0.098906324 | K29: =D29/($D$32+$D$40) -> 0.053965973 | L29: =E29/($E$32+$E$38) -> 0.081470775
A30: Provisions | B30: 1935000000 | C30: 1801000000 | D30: 2139000000 | E30: 2698000000 | G30: =D30-C30 -> 338000000 | H30: =(D30-C30)/C30 -> 0.18767351 | I30: =E30-D30 -> 559000000 | J30: =(E30-D30)/D30 -> 0.26133707 | K30: =D30/($D$32+$D$40) -> 0.054889784 | L30: =E30/($E$32+$E$38) -> 0.095113869
A31: Other | B31: 13101000000 | C31: 21000000 | D31: 21000000 | E31: 48000000 | G31: =D31-C31 -> 0 | H31: =(D31-C31)/C31 -> 0 | I31: =E31-D31 -> 27000000 | J31: =(E31-D31)/D31 -> 1.2857143 | K31: =D31/($D$32+$D$40) -> 0.00053888989 | L31: =E31/($E$32+$E$38) -> 0.0016921667
A32: Total Current Liabilities | B32: =SUM(B28:B31) -> 23117000000 | C32: =SUM(C28:C31) -> 10750000000 | D32: =SUM(D28:D31) -> 11886000000 | E32: =SUM(E28:E31) -> 12819000000 | G32: =D32-C32 -> 1136000000 | H32: =(D32-C32)/C32 -> 0.10567442 | I32: =E32-D32 -> 933000000 | J32: =(E32-D32)/D32 -> 0.078495709 | K32: =D32/($D$32+$D$40) -> 0.30501168 | L32: =E32/($E$32+$E$38) -> 0.45191426
K33: =D33/($D$32+$D$40) -> 0 | L33: =E33/($E$32+$E$38) -> 0
A34: Non-Current Liabilities | K34: =D34/($D$32+$D$40) -> 0 | L34: =E34/($E$32+$E$38) -> 0
A35: Long-Term Debt | B35: 13274000000 | C35: 14837000000 | D35: 13632000000 | E35: 14411000000 | G35: =D35-C35 -> -1205000000 | H35: =(D35-C35)/C35 -> -0.081215879 | I35: =E35-D35 -> 779000000 | J35: =(E35-D35)/D35 -> 0.057144953 | K35: =D35/($D$32+$D$38) -> 0.50334158 | L35: =E35/($E$32+$E$38) -> 0.50803779
A36: Provisions | B36: 1055000000 | C36: 1536000000 | D36: 1526000000 | E36: 1103000000 | G36: =D36-C36 -> -10000000 | H36: =(D36-C36)/C36 -> -0.0065104167 | I36: =E36-D36 -> -423000000 | J36: =(E36-D36)/D36 -> -0.27719528 | K36: =D36/($D$32+$D$38) -> 0.056345309 | L36: =E36/($E$32+$E$38) -> 0.03888458
A37: Other | B37: 51000000 | C37: 46000000 | D37: 39000000 | E37: 33000000 | G37: =D37-C37 -> -7000000 | H37: =(D37-C37)/C37 -> -0.15217391 | I37: =E37-D37 -> -6000000 | J37: =(E37-D37)/D37 -> -0.15384615 | K37: =D37/($D$32+$D$38) -> 0.0014400177 | L37: =E37/($E$32+$E$38) -> 0.0011633646
A38: Total Non-Current Liabilities | B38: =SUM(B35:B37) -> 14380000000 | C38: =SUM(C35:C37) -> 16419000000 | D38: =SUM(D35:D37) -> 15197000000 | E38: =SUM(E35:E37) -> 15547000000 | G38: =D38-C38 -> -1222000000 | H38: =(D38-C38)/C38 -> -0.07442597 | I38: =E38-D38 -> 350000000 | J38: =(E38-D38)/D38 -> 0.023030861 | K38: =D38/($D$32+$D$38) -> 0.56112691 | L38: =E38/($E$32+$E$38) -> 0.54808574
A40: Total Liabilities | B40: =B38+B32 -> 37497000000 | C40: =C38+C32 -> 27169000000 | D40: =D38+D32 -> 27083000000 | E40: =E38+E32 -> 28366000000 | G40: =D40-C40 -> -86000000 | H40: =(D40-C40)/C40 -> -0.0031653723 | I40: =E40-D40 -> 1283000000 | J40: =(E40-D40)/D40 -> 0.047372891 | K40: =D40/($D$32+$D$38) -> 1 | L40: =E40/($E$32+$E$38) -> 1
A42: Equity
A43: Share Capital | B43: 5253000000 | C43: 5207000000 | D43: 5406000000 | E43: 5604000000 | G43: =D43-C43 -> 199000000 | H43: =(D43-C43)/C43 -> 0.038217784 | I43: =E43-D43 -> 198000000 | J43: =(E43-D43)/D43 -> 0.036625971 | K43: =D43/($D$47) -> 0.82345773 | L43: =E43/($E$47) -> 1.0061041
A44: Reserves | B44: -6989000000 | C44: -7400000000 | D44: -7567000000 | E44: -7609000000 | G44: =D44-C44 -> -167000000 | H44: =(D44-C44)/C44 -> 0.022567568 | I44: =E44-D44 -> -42000000 | J44: =(E44-D44)/D44 -> 0.0055504163 | K44: =D44/($D$47) -> -1.1526276 | L44: =E44/($E$47) -> -1.3660682
A45: Retained Earnings | B45: 3115000000 | C45: 8173000000 | D45: 8586000000 | E45: 7413000000 | G45: =D45-C45 -> 413000000 | H45: =(D45-C45)/C45 -> 0.05053224 | I45: =E45-D45 -> -1173000000 | J45: =(E45-D45)/D45 -> -0.13661775 | K45: =D45/($D$47) -> 1.3078446 | L45: =E45/($E$47) -> 1.3308797
...

Sheet Income Statement - COL
A1: Income Statement | G1: Trend Analysis | H1: Horiztonal Analysis | L1: Vertical Analysis
A2: Coles Group Limited
B3: 2021 | C3: 2022 | D3: 2023 | E3: 2024 | G3: 2021-2024 | H3: 2023 $Change | I3: 2023 % Change | J3: 2024 $ Change | K3: 2024 % Change | L3: 2023 | M3: 2024 | O3: Notes
A4: Revenues
A5: Operating Revenue | B5: 38562000000 | C5: 39369000000 | D5: 40483000000 | E5: 43571000000 | H5: =D5-C5 -> 1114000000 | I5: =(D5-C5)/C5 -> 0.028296375 | J5: =E5-D5 -> 3088000000 | K5: =(E5-D5)/D5 -> 0.076278932 | L5: =D5/$D$5 -> 1 | M5: =E5/$E$5 -> 1 | O5: # Sparklines provide a very quick and easy way to graph changes in data.
A6: Other Revenue | B6: 481000000 | C6: 473000000 | D6: =271000000+56000000 -> 327000000 | E6: =278000000-10000000 -> 268000000 | H6: =D6-C6 -> -146000000 | I6: =(D6-C6)/C6 -> -0.30866808 | J6: =E6-D6 -> -59000000 | K6: =(E6-D6)/D6 -> -0.18042813 | L6: =D6/$D$5 -> 0.0080774646 | M6: =E6/$E$5 -> 0.0061508802
A8: Expenses
A9: Cost of Sales | B9: 28773000000 | C9: 29210000000 | D9: 30034000000 | E9: 32299000000 | H9: =D9-C9 -> 824000000 | I9: =(D9-C9)/C9 -> 0.028209517 | J9: =E9-D9 -> 2265000000 | K9: =(E9-D9)/D9 -> 0.07541453 | L9: =D9/$D$5 -> 0.74189166 | M9: =E9/$E$5 -> 0.74129582
A10: Employee benefits expense | B10: 4898000000 | C10: 5085000000 | D10: 5118000000 | E10: 5512000000 | H10: =D10-C10 -> 33000000 | I10: =(D10-C10)/C10 -> 0.0064896755 | J10: =E10-D10 -> 394000000 | K10: =(E10-D10)/D10 -> 0.076983197 | L10: =D10/$D$5 -> 0.12642344 | M10: =E10/$E$5 -> 0.12650616 | O10: *Note: I have used positive numbers consistently. The annual report uses negative numbers for expenses. As I know Raw Materials Expense is an expense, I minus the positive number from revenue to calculate profit. Alternatively, if you use a negative sign for expenses, you plus revenues and expenses to calculate profit.
A11: Occupancy and overheads | B11: 707000000 | C11: 734000000 | D11: 774000000 | E11: 882000000 | H11: =D11-C11 -> 40000000 | I11: =(D11-C11)/C11 -> 0.054495913 | J11: =E11-D11 -> 108000000 | K11: =(E11-D11)/D11 -> 0.13953488 | L11: =D11/$D$5 -> 0.019119136 | M11: =E11/$E$5 -> 0.020242822
A12: Depreciation and amortisation | B12: 1513000000 | C12: 1524000000 | D12: 1461000000 | E12: 1517000000 | H12: =D12-C12 -> -63000000 | I12: =(D12-C12)/C12 -> -0.041338583 | J12: =E12-D12 -> 56000000 | K12: =(E12-D12)/D12 -> 0.038329911 | L12: =D12/$D$5 -> 0.036089223 | M12: =E12/$E$5 -> 0.034816736
A13: Marketing expenses | B13: 242000000 | C13: 241000000 | D13: 234000000 | E13: 233000000 | H13: =D13-C13 -> -7000000 | I13: =(D13-C13)/C13 -> -0.029045643 | J13: =E13-D13 -> -1000000 | K13: =(E13-D13)/D13 -> -0.0042735043 | L13: =D13/$D$5 -> 0.005780204 | M13: =E13/$E$5 -> 0.0053475936 | O13: *Impairment costs weren't listed every year. Be careful that the accounts and order may change between financial statements
A14: Net impairment expense/(reversal) | B14: -3000000 | C14: -10000000 | D14: -11000000 | E14: 55000000 | H14: =D14-C14 -> -1000000 | I14: =(D14-C14)/C14 -> 0.1 | J14: =E14-D14 -> 66000000 | K14: =(E14-D14)/D14 -> -6 | L14: =D14/$D$5 -> -0.00027171899 | M14: =E14/$E$5 -> 0.0012623075 | O14: #DIV/0! Is an error. Excel is telling you the formula tried to divide by 0, which is mathematically not possible to compute.
A15: Other store expenses | B15: 623000000 | C15: 610000000 | D15: 668000000 | E15: 655000000 | H15: =D15-C15 -> 58000000 | I15: =(D15-C15)/C15 -> 0.095081967 | J15: =E15-D15 -> -13000000 | K15: =(E15-D15)/D15 -> -0.019461078 | L15: =D15/$D$5 -> 0.016500753 | M15: =E15/$E$5 -> 0.015032935
A16: Other administration expenses | B16: 412000000 | C16: 572000000 | D16: 604000000 | E16: 621000000 | H16: =D16-C16 -> 32000000 | I16: =(D16-C16)/C16 -> 0.055944056 | J16: =E16-D16 -> 17000000 | K16: =(E16-D16)/D16 -> 0.028145695 | L16: =D16/$D$5 -> 0.014919843 | M16: =E16/$E$5 -> 0.014252599
A17: Interest on debt and borrowings | B17: 23000000 | C17: 16000000 | D17: 28000000 | E17: 48000000 | H17: =D17-C17 -> 12000000 | I17: =(D17-C17)/C17 -> 0.75 | J17: =E17-D17 -> 20000000 | K17: =(E17-D17)/D17 -> 0.71428571 | L17: =D17/$D$5 -> 0.00069164835 | M17: =E17/$E$5 -> 0.0011016502
A18: Interest on lease liabilities | B18: 390000000 | C18: 363000000 | D18: 343000000 | E18: 363000000 | H18: =D18-C18 -> -20000000 | I18: =(D18-C18)/C18 -> -0.055096419 | J18: =E18-D18 -> 20000000 | K18: =(E18-D18)/D18 -> 0.058309038 | L18: =D18/$D$5 -> 0.0084726922 | M18: =E18/$E$5 -> 0.0083312295
A19: Other finance related costs | B19: 14000000 | C19: 17000000 | D19: 23000000 | E19: 31000000 | H19: =D19-C19 -> 6000000 | I19: =(D19-C19)/C19 -> 0.35294118 | J19: =E19-D19 -> 8000000 | K19: =(E19-D19)/D19 -> 0.34782609 | L19: =D19/$D$5 -> 0.00056813971 | M19: =E19/$E$5 -> 0.00071148241 | O19: * Use the =SUM function to check if your numbers equal the Income Statement total
A20: Share of net loss from equity accounted investments | B20: 5000000 | C20: 7000000 | D20: 13000000 | E20: 18000000 | H20: =D20-C20 -> 6000000 | I20: =(D20-C20)/C20 -> 0.85714286 | J20: =E20-D20 -> 5000000 | K20: =(E20-D20)/D20 -> 0.38461538 | L20: =D20/$D$5 -> 0.00032112245 | M20: =E20/$E$5 -> 0.00041311882
A22: Profit before income tax | B22: =SUM(B5:B6)-SUM(B9:B20) -> 1446000000 | C22: =SUM(C5:C6)-SUM(C9:C20) -> 1473000000 | D22: =SUM(D5:D6)-SUM(D9:D20) -> 1521000000 | E22: =SUM(E5:E6)-SUM(E9:E20) -> 1605000000 | H22: =D22-C22 -> 48000000 | I22: =(D22-C22)/C22 -> 0.032586558 | J22: =E22-D22 -> 84000000 | K22: =(E22-D22)/D22 -> 0.055226824 | L22: =D22/$D$5 -> 0.037571326 | M22: =E22/$E$5 -> 0.036836428 | O22: * Use the =SUM function to check if your numbers equal the Income Statement total
A24: Income Tax Expense | B24: 441000000 | C24: 425000000 | D24: 423000000 | E24: 487000000 | H24: =D24-C24 -> -2000000 | I24: =(D24-C24)/C24 -> -0.0047058824 | J24: =E24-D24 -> 64000000 | K24: =(E24-D24)/D24 -> 0.15130024 | L24: =D24/$D$5 -> 0.01044883 | M24: =E24/$E$5 -> 0.011177159 | O24: *Note: I have used positive numbers consistently. The annual report uses negative numbers for expenses. As I know Tax Expense is an expense, I minus the positive number from profits. Alternatively, if you use a negative sign for expenses, you plus revenues and expenses to calculate profit.
A25: Net Profit After Tax | B25: =B22-B24 -> 1005000000 | C25: =C22-C24 -> 1048000000 | D25: =D22-D24 -> 1098000000 | E25: =E22-E24 -> 1118000000 | H25: =D25-C25 -> 50000000 | I25: =(D25-C25)/C25 -> 0.047709924 | J25: =E25-D25 -> 20000000 | K25: =(E25-D25)/D25 -> 0.018214936 | L25: =D25/$D$5 -> 0.027122496 | M25: =E25/$E$5 -> 0.025659269 | O25: * Use the =SUM function to check if your numbers equal the Income Statement total
A27: Other Comprehensive Income | B27: -6000000 | C27: 22000000 | D27: 10000000 | E27: -3000000 | H27: =D27-C27 -> -12000000 | I27: =(D27-C27)/C27 -> -0.54545455 | J27: =E27-D27 -> -13000000 | K27: =(E27-D27)/D27 -> -1.3 | L27: =D27/$D$5 -> 0.00024701727 | M27: =E27/$E$5 -> -6.8853136e-05
A29: Comprehensive Income | B29: =B25+B27 -> 999000000 | C29: =C25+C27 -> 1070000000 | D29: =D25+D27 -> 1108000000 | E29: =E25+E27 -> 1115000000 | H29: =D29-C29 -> 38000000 | I29: =(D29-C29)/C29 -> 0.035514019 | J29: =E29-D29 -> 7000000 | K29: =(E29-D29)/D29 -> 0.0063176895 | L29: =D29/$D$5 -> 0.027369513 | M29: =E29/$E$5 -> 0.025590416 | O29: * Use the =SUM function to check if your numbers equal the Income Statement total

Sheet Income Statement - WOW
A1: Income Statement | G1: Trend Analysis | H1: Horiztonal Analysis | L1: Vertical Analysis
A2: Woolworths Group Limited
B3: 2021 | C3: 2022 | D3: 2023 | E3: 2024 | G3: 2021-2024 | H3: 2023 $Change | I3: 2023 % Change | J3: 2024 $ Change | K3: 2024 % Change | L3: 2023 | M3: 2024 | O3: Notes
A4: Revenues
A5: Operating Revenue | B5: 55694000000 | C5: 60849000000 | D5: 64294000000 | E5: 67922000000 | H5: =D5-C5 -> 3445000000 | I5: =(D5-C5)/C5 -> 0.056615557 | J5: =E5-D5 -> 3628000000 | K5: =(E5-D5)/D5 -> 0.056428283 | L5: =D5/$D$5 -> 1 | M5: =E5/$E$5 -> 1 | O5: # Sparklines provide a very quick and easy way to graph changes in data.
A6: Other Revenue | B6: 117000000 | C6: 297000000 | D6: 277000000 | E6: 310000000 | H6: =D6-C6 -> -20000000 | I6: =(D6-C6)/C6 -> -0.067340067 | J6: =E6-D6 -> 33000000 | K6: =(E6-D6)/D6 -> 0.11913357 | L6: =D6/$D$5 -> 0.0043083336 | M6: =E6/$E$5 -> 0.0045640588
A8: Expenses
A9: Cost of Sales | B9: 39366000000 | C9: 44878000000 | D9: 47118000000 | E9: 49370000000 | H9: =D9-C9 -> 2240000000 | I9: =(D9-C9)/C9 -> 0.049913098 | J9: =E9-D9 -> 2252000000 | K9: =(E9-D9)/D9 -> 0.047794898 | L9: =D9/$D$5 -> 0.73285221 | M9: =E9/$E$5 -> 0.72686317
A10: Administration expenses | B10: 3784000000 | C10: 3189000000 | D10: 3684000000 | E10: 5539000000 | H10: =D10-C10 -> 495000000 | I10: =(D10-C10)/C10 -> 0.15522107 | J10: =E10-D10 -> 1855000000 | K10: =(E10-D10)/D10 -> 0.50352877 | L10: =D10/$D$5 -> 0.057299281 | M10: =E10/$E$5 -> 0.081549424
A11: Branch Expenses | B11: 9838000000 | C11: 10388000000 | D11: 10770000000 | E11: 11707000000 | H11: =D11-C11 -> 382000000 | I11: =(D11-C11)/C11 -> 0.0367732 | J11: =E11-D11 -> 937000000 | K11: =(E11-D11)/D11 -> 0.087000929 | L11: =D11/$D$5 -> 0.16751174 | M11: =E11/$E$5 -> 0.17235947
A12: Employee Benefits Expense | C12: 8557000000 | D12: 8762000000 | E12: 9519000000 | H12: =D12-C12 -> 205000000 | I12: =(D12-C12)/C12 -> 0.023956994 | J12: =E12-D12 -> 757000000 | K12: =(E12-D12)/D12 -> 0.0863958 | L12: =D12/$D$5 -> 0.13628021 | M12: =E12/$E$5 -> 0.14014605
A13: Depreciation and Amortisation | C13: 2132000000 | D13: 2309000000 | E13: 2452000000 | H13: =D13-C13 -> 177000000 | I13: =(D13-C13)/C13 -> 0.083020638 | J13: =E13-D13 -> 143000000 | K13: =(E13-D13)/D13 -> 0.061931572 | L13: =D13/$D$5 -> 0.035913149 | M13: =E13/$E$5 -> 0.036100233
A14: Occupancy Expense | C14: 624000000 | D14: 611000000 | E14: 706000000 | H14: =D14-C14 -> -13000000 | I14: =(D14-C14)/C14 -> -0.020833333 | J14: =E14-D14 -> 95000000 | K14: =(E14-D14)/D14 -> 0.15548282 | L14: =D14/$D$5 -> 0.0095032196 | M14: =E14/$E$5 -> 0.010394276
A15: Contract Labour | C15: 745000000 | D15: 832000000 | E15: 825000000 | H15: =D15-C15 -> 87000000 | I15: =(D15-C15)/C15 -> 0.11677852 | J15: =E15-D15 -> -7000000 | K15: =(E15-D15)/D15 -> -0.0084134615 | L15: =D15/$D$5 -> 0.012940554 | M15: =E15/$E$5 -> 0.012146285
A16: Other Administration and Branch Expenses | C16: 1519000000 | D16: 1940000000 | E16: 3744000000 | H16: =D16-C16 -> 421000000 | I16: =(D16-C16)/C16 -> 0.27715602 | J16: =E16-D16 -> 1804000000 | K16: =(E16-D16)/D16 -> 0.92989691 | L16: =D16/$D$5 -> 0.030173889 | M16: =E16/$E$5 -> 0.055122052
A17: Interest on debt and borrowings | B17: 102000000 | C17: 90000000 | D17: 184000000 | E17: =225000000+17000000 -> 242000000 | H17: =D17-C17 -> 94000000 | I17: =(D17-C17)/C17 -> 1.0444444 | J17: =E17-D17 -> 58000000 | K17: =(E17-D17)/D17 -> 0.31521739 | L17: =D17/$D$5 -> 0.0028618534 | M17: =E17/$E$5 -> 0.0035629104
A18: Interest on lease liabilities | B18: 528000000 | C18: 542000000 | D18: 542000000 | E18: 570000000 | H18: =D18-C18 -> 0 | I18: =(D18-C18)/C18 -> 0 | J18: =E18-D18 -> 28000000 | K18: =(E18-D18)/D18 -> 0.051660517 | L18: =D18/$D$5 -> 0.0084300246 | M18: =E18/$E$5 -> 0.008391979
A19: Less: Interest Capitalised | B19: -10000000 | C19: -13000000 | D19: -28000000 | E19: -40000000 | H19: =D19-C19 -> -15000000 | I19: =(D19-C19)/C19 -> 1.1538462 | J19: =E19-D19 -> -12000000 | K19: =(E19-D19)/D19 -> 0.42857143 | L19: =D19/$D$5 -> -0.00043549942 | M19: =E19/$E$5 -> -0.00058891081
A20: Other finance related costs | B20: -7000000 | C20: -19000000 | D20: -21000000 | E20: -32000000 | H20: =D20-C20 -> -2000000 | I20: =(D20-C20)/C20 -> 0.10526316 | J20: =E20-D20 -> -11000000 | K20: =(E20-D20)/D20 -> 0.52380952 | L20: =D20/$D$5 -> -0.00032662457 | M20: =E20/$E$5 -> -0.00047112865 | O20: * Use the =SUM function to check if your numbers equal the Income Statement total
A22: Profit before income tax | B22: =SUM(B5:B6)-SUM(B9:B20) -> 2210000000 | C22: =SUM(C5:C6)-(SUM(C9:C20)-SUM(C12:C16)) -> 2091000000 | D22: =SUM(D5:D6)-(SUM(D9:D20)-SUM(D12:D16)) -> 2322000000 | E22: =SUM(E5:E6)-(SUM(E9:E20)-SUM(E12:E16)) -> 876000000 | H22: =D22-C22 -> 231000000 | I22: =(D22-C22)/C22 -> 0.11047346 | J22: =E22-D22 -> -1446000000 | K22: =(E22-D22)/D22 -> -0.62273902 | L22: =D22/$D$5 -> 0.036115345 | M22: =E22/$E$5 -> 0.012897147 | O22: * Use the =SUM function to check if your numbers equal the Income Statement total
A24: Income Tax Expense | B24: 604000000 | C24: 534000000 | D24: 693000000 | E24: 759000000 | H24: =D24-C24 -> 159000000 | I24: =(D24-C24)/C24 -> 0.29775281 | J24: =E24-D24 -> 66000000 | K24: =(E24-D24)/D24 -> 0.095238095 | L24: =D24/$D$5 -> 0.010778611 | M24: =E24/$E$5 -> 0.011174583 | O24: *Note: I have used positive numbers consistently. The annual report uses negative numbers for expenses. As I know Tax Expense is an expense, I minus the positive number from profits. Alternatively, if you use a negative sign for expenses, you plus revenues and expenses to calculate profit.
A25: Net Profit After Tax | B25: =B22-B24 -> 1606000000 | C25: =C22-C24 -> 1557000000 | D25: =D22-D24 -> 1629000000 | E25: =E22-E24 -> 117000000 | H25: =D25-C25 -> 72000000 | I25: =(D25-C25)/C25 -> 0.046242775 | J25: =E25-D25 -> -1512000000 | K25: =(E25-D25)/D25 -> -0.9281768 | L25: =D25/$D$5 -> 0.025336734 | M25: =E25/$E$5 -> 0.0017225641 | O25: * Use the =SUM function to check if your numbers equal the Income Statement total
A27: Other Comprehensive Income | B27: 533000000 | C27: 6387000000 | D27: 0 | E27: 0 | H27: =D27-C27 -> -6387000000 | I27: 0 | J27: =E27-D27 -> 0 | K27: 0 | L27: =D27/$D$5 -> 0 | M27: =E27/$E$5 -> 0
A29: Comprehensive Income | B29: =B25+B27 -> 2139000000 | C29: =C25+C27 -> 7944000000 | D29: =D25+D27 -> 1629000000 | E29: =E25+E27 -> 117000000 | H29: =D29-C29 -> -6315000000 | I29: =(D29-C29)/C29 -> -0.79493958 | J29: =E29-D29 -> -1512000000 | K29: =(E29-D29)/D29 -> -0.9281768 | L29: =D29/$D$5 -> 0.025336734 | M29: =E29/$E$5 -> 0.0017225641 | O29: * Use the =SUM function to check if your numbers equal the Income Statement total

Sheet Sheet3
A1: Expenses
A2: Cost of Sales | B2: 28773000000 | C2: 29210000000 | D2: 30034000000 | E2: 32299000000 | H2: =D2-C2 -> 824000000 | I2: =(D2-C2)/C2 -> 0.028209517 | J2: =E2-D2 -> 2265000000 | K2: =(E2-D2)/D2 -> 0.07541453
A3: Employee benefits expense | B3: 4898000000 | C3: 5085000000 | D3: 5118000000 | E3: 5512000000 | H3: =D3-C3 -> 33000000 | I3: =(D3-C3)/C3 -> 0.0064896755 | J3: =E3-D3 -> 394000000 | K3: =(E3-D3)/D3 -> 0.076983197
A4: Occupancy and overheads | B4: 707000000 | C4: 734000000 | D4: 774000000 | E4: 882000000 | H4: =D4-C4 -> 40000000 | I4: =(D4-C4)/C4 -> 0.054495913 | J4: =E4-D4 -> 108000000 | K4: =(E4-D4)/D4 -> 0.13953488
A5: Depreciation and amortisation | B5: 1513000000 | C5: 1524000000 | D5: 1461000000 | E5: 1517000000 | H5: =D5-C5 -> -63000000 | I5: =(D5-C5)/C5 -> -0.041338583 | J5: =E5-D5 -> 56000000 | K5: =(E5-D5)/D5 -> 0.038329911
A6: Marketing expenses | B6: 242000000 | C6: 241000000 | D6: 234000000 | E6: 233000000 | H6: =D6-C6 -> -7000000 | I6: =(D6-C6)/C6 -> -0.029045643 | J6: =E6-D6 -> -1000000 | K6: =(E6-D6)/D6 -> -0.0042735043
A7: Net impairment expense/(reversal) | B7: -3000000 | C7: -10000000 | D7: -11000000 | E7: 55000000 | H7: =D7-C7 -> -1000000 | I7: =(D7-C7)/C7 -> 0.1 | J7: =E7-D7 -> 66000000 | K7: =(E7-D7)/D7 -> -6
A8: Other store expenses | B8: 623000000 | C8: 610000000 | D8: 668000000 | E8: 655000000 | H8: =D8-C8 -> 58000000 | I8: =(D8-C8)/C8 -> 0.095081967 | J8: =E8-D8 -> -13000000 | K8: =(E8-D8)/D8 -> -0.019461078
A9: Other administration expenses | B9: 412000000 | C9: 572000000 | D9: 604000000 | E9: 621000000 | H9: =D9-C9 -> 32000000 | I9: =(D9-C9)/C9 -> 0.055944056 | J9: =E9-D9 -> 17000000 | K9: =(E9-D9)/D9 -> 0.028145695
A10: Interest on debt and borrowings | B10: 23000000 | C10: 16000000 | D10: 28000000 | E10: 48000000 | H10: =D10-C10 -> 12000000 | I10: =(D10-C10)/C10 -> 0.75 | J10: =E10-D10 -> 20000000 | K10: =(E10-D10)/D10 -> 0.71428571
A11: Interest on lease liabilities | B11: 390000000 | C11: 363000000 | D11: 343000000 | E11: 363000000 | H11: =D11-C11 -> -20000000 | I11: =(D11-C11)/C11 -> -0.055096419 | J11: =E11-D11 -> 20000000 | K11: =(E11-D11)/D11 -> 0.058309038
A12: Other finance related costs | B12: 14000000 | C12: 17000000 | D12: 23000000 | E12: 31000000 | H12: =D12-C12 -> 6000000 | I12: =(D12-C12)/C12 -> 0.35294118 | J12: =E12-D12 -> 8000000 | K12: =(E12-D12)/D12 -> 0.34782609
A13: Share of net loss from equity accounted investments | B13: 5000000 | C13: 7000000 | D13: 13000000 | E13: 18000000 | H13: =D13-C13 -> 6000000 | I13: =(D13-C13)/C13 -> 0.85714286 | J13: =E13-D13 -> 5000000 | K13: =(E13-D13)/D13 -> 0.38461538
B14: =SUM(B2:B13) -> 37597000000 | C14: =SUM(C2:C13) -> 38369000000 | D14: =SUM(D2:D13) -> 39289000000 | E14: =SUM(E2:E13) -> 42234000000 | H14: =D14-C14 -> 920000000 | I14: =(D14-C14)/C14 -> 0.02397769 | J14: =E14-D14 -> 2945000000 | K14: =(E14-D14)/D14 -> 0.074957367

Sheet Cash Flow Statement - COL
A1: Cash Flow Statement | F1: Trend Analysis | G1: Horiztonal Analysis | K1: Vertical Analysis | M1: Notes:
A2: Coles Group Limited
B3: 2021 | C3: 2022 | D3: 2023 | E3: 2024 | F3: 2021-2024 | G3: 2023 $Change | H3: 2023 % Change | I3: 2024 $ Change | J3: 2024 % Change | K3: 2023 | L3: 2024
A4: Cash flow from Operations | B4: 2837000000 | C4: 2690000000 | D4: 2807000000 | E4: 2793000000 | G4: =D4-C4 -> 117000000 | H4: =(D4-C4)/C4 -> 0.043494424 | I4: =E4-D4 -> -14000000 | J4: =I4/D4 -> -0.0049875312 | K4: =D4/'Income Statement - COL'!D5 -> 0.069337747 | L4: =E4/'Income Statement - COL'!E5 -> 0.06410227 | M4: * To conduct Vertical Analysis of the Cash Flow Statement, you can divide by Revenue (From the Income Statement), to get Cash Flow as a percentage of Revenues, or by Total Cash Inflow. I have divided by Revenue
A5: Cash flow from Investing Activities | B5: -1106000000 | C5: -1142000000 | D5: -1000000000 | E5: -1513000000 | G5: =D5-C5 -> 142000000 | H5: =(D5-C5)/C5 -> -0.12434326 | I5: =E5-D5 -> -513000000 | J5: =I5/D5 -> 0.513 | K5: =D5/'Income Statement - COL'!D5 -> -0.024701727 | L5: =E5/'Income Statement - COL'!E5 -> -0.034724932
A6: Cash flow from Financing Activities | B6: -1936000000 | C6: -1746000000 | D6: -1799000000 | E6: -1202000000 | G6: =D6-C6 -> -53000000 | H6: =(D6-C6)/C6 -> 0.030355097 | I6: =E6-D6 -> 597000000 | J6: =I6/D6 -> -0.33185103 | K6: =D6/'Income Statement - COL'!D5 -> -0.044438406 | L6: =E6/'Income Statement - COL'!E5 -> -0.027587157

Sheet Cash Flow Statement - WOW
A1: Cash Flow Statement | F1: Trend Analysis | G1: Horiztonal Analysis | K1: Vertical Analysis | M1: Notes:
A2: Coles Group Limited
B3: 2021 | C3: 2022 | D3: 2023 | E3: 2024 | F3: 2021-2024 | G3: 2023 $Change | H3: 2023 % Change | I3: 2024 $ Change | J3: 2024 % Change | K3: 2023 | L3: 2024
A4: Cash flow from Operations | B4: 4624000000 | C4: 3378000000 | D4: 4754000000 | E4: 4359000000 | G4: =D4-C4 -> 1376000000 | H4: =(D4-C4)/C4 -> 0.40734162 | I4: =E4-D4 -> -395000000 | J4: =I4/D4 -> -0.083087926 | K4: =D4/'Income Statement - WOW'!D5 -> 0.073941581 | L4: =E4/'Income Statement - WOW'!E5 -> 0.064176555 | M4: * To conduct Vertical Analysis of the Cash Flow Statement, you can divide by Revenue (From the Income Statement), to get Cash Flow as a percentage of Revenues, or by Total Cash Inflow. I have divided by Revenue
A5: Cash flow from Investing Activities | B5: -2200000000 | C5: -2457000000 | D5: -1844000000 | E5: -2277000000 | G5: =D5-C5 -> 613000000 | H5: =(D5-C5)/C5 -> -0.24949125 | I5: =E5-D5 -> -433000000 | J5: =I5/D5 -> 0.23481562 | K5: =D5/'Income Statement - WOW'!D5 -> -0.028680748 | L5: =E5/'Income Statement - WOW'!E5 -> -0.033523748
A6: Cash flow from Financing Activities | B6: -3043000000 | C6: -1337000000 | D6: -2809000000 | E6: -1919000000 | G6: =D6-C6 -> -1472000000 | H6: =(D6-C6)/C6 -> 1.1009723 | I6: =E6-D6 -> 890000000 | J6: =I6/D6 -> -0.31683873 | K6: =D6/'Income Statement - WOW'!D5 -> -0.043689924 | L6: =E6/'Income Statement - WOW'!E5 -> -0.028252996

Sheet Market Cap - COL
A1: Coles Grop Limited | B1: 2021 | C1: 2022 | D1: 2023 | E1: 2024 | G1: Note:
A2: Number of Ordinary Shares | B2: 1333900000 | C2: 1336100000 | D2: 1338400000 | E2: 1339400000 | G2: This is the actual number of shares. Other numbers in the Financial statements are expressed in ,000s
A3: Share Price | B3: 16.83 | C3: 17.81 | D3: 18.4 | E3: 17.03
A4: Market Capitalisation | B4: =B2*B3 -> 2.2449537e+10 | C4: =C2*C3 -> 23795941000 | D4: =D2*D3 -> 24626560000 | E4: =E2*E3 -> 22809982000

Sheet Market Cap - WOW
A1: Coles Grop Limited | B1: 2021 | C1: 2022 | D1: 2023 | E1: 2024 | G1: Note:
A2: Number of Ordinary Shares | B2: 1267700000 | C2: 1213900000 | D2: 1218700000 | E2: 1221600000 | G2: This is the actual number of shares. Other numbers in the Financial statements are expressed in ,000s
A3: Share Price | B3: 42.88 | C3: 35.46 | D3: 39.86 | E3: 33.79
A4: Market Capitalisation | B4: =B2*B3 -> 54358976000 | C4: =C2*C3 -> 43044894000 | D4: =D2*D3 -> 48577382000 | E4: =E2*E3 -> 41277864000

Sheet Ratio Analysis - COL
C1: Coles Group Limited Ratio Analysis
H2: Notes:
A3: Profitability Ratios | B3: Formula | C3: 2021 | D3: 2022 | E3: 2023 | F3: 2024
A4: Return on Equity (ROE) | B4: Net Profit / Average Equity | D4: ='Income Statement - COL'!C25/AVERAGE('Balance Sheet - COL'!$B$44:$C$44) -> 0.35304026 | E4: ='Income Statement - COL'!D25/AVERAGE('Balance Sheet - COL'!$C$44:$D$44) -> 0.33888889 | F4: ='Income Statement - COL'!E25/AVERAGE('Balance Sheet - COL'!$D$44:$E$44) -> 0.32066542 | H4: Explain change in the net profit w.r.t change in Average equity
A5: Return on Assets (ROA) | B5: Net Profit / Average Total Assets | D5: ='Income Statement - COL'!C25/AVERAGE(('Balance Sheet - COL'!C21+'Balance Sheet - COL'!C12),('Balance Sheet - COL'!B21+'Balance Sheet - COL'!B12)) -> 0.056711491 | E5: ='Income Statement - COL'!D25/AVERAGE(('Balance Sheet - COL'!D21+'Balance Sheet - COL'!D12),('Balance Sheet - COL'!C21+'Balance Sheet - COL'!C12)) -> 0.059146736 | F5: ='Income Statement - COL'!E25/AVERAGE(('Balance Sheet - COL'!E21+'Balance Sheet - COL'!E12),('Balance Sheet - COL'!D21+'Balance Sheet - COL'!D12)) -> 0.058592317 | H5: Return on assets | I5: Operating Revenue growth
A6: Profit Margin (PM) | B6: Net Profit / Sales Revenue | C6: ='Income Statement - COL'!B25/'Income Statement - COL'!B5 -> 0.026061926 | D6: ='Income Statement - COL'!C25/'Income Statement - COL'!C5 -> 0.026619929 | E6: ='Income Statement - COL'!D25/'Income Statement - COL'!D5 -> 0.027122496 | F6: ='Income Statement - COL'!E25/'Income Statement - COL'!E5 -> 0.025659269
A7: Cash Flow Margin | B7: Cash Flow from Operating Activities / Sales Revenue | C7: ='Cash Flow Statement - COL'!B4/'Income Statement - COL'!B5 -> 0.073569836 | D7: ='Cash Flow Statement - COL'!C4/'Income Statement - COL'!C5 -> 0.068327872 | E7: ='Cash Flow Statement - COL'!D4/'Income Statement - COL'!D5 -> 0.069337747 | F7: ='Cash Flow Statement - COL'!E4/'Income Statement - COL'!E5 -> 0.06410227
A9: Efficiency Ratios
A10: Asset Turnover Ratio (ATO) | B10: Sales Revenue / Average Total Assets | D10: ='Income Statement - COL'!C5/AVERAGE('Balance Sheet - COL'!B23:C23) -> 2.1304148 | E10: ='Income Statement - COL'!D5/AVERAGE('Balance Sheet - COL'!C23:D23) -> 2.1807261 | F10: ='Income Statement - COL'!E5/AVERAGE('Balance Sheet - COL'!D23:E23) -> 2.2834757
A11: Days Inventory | B11: Average Inventory / Cost of Sales * 365 days | D11: =AVERAGE('Balance Sheet - COL'!B9:C9)/SUM('Income Statement - COL'!C9)*365 -> 28.459004 | E11: =AVERAGE('Balance Sheet - COL'!C9:D9)/SUM('Income Statement - COL'!D9)*365 -> 28.990727 | F11: =AVERAGE('Balance Sheet - COL'!D9:E9)/SUM('Income Statement - COL'!E9)*365 -> 28.398557
A12: Days in Receivables | B12: Average Accounts Receivable / Sales Revenue * 365 days | D12: =AVERAGE('Balance Sheet - COL'!B7:C7)/'Income Statement - COL'!C5*365 -> 3.8846554 | E12: =AVERAGE('Balance Sheet - COL'!C7:D7)/'Income Statement - COL'!D5*365 -> 4.84617 | F12: =AVERAGE('Balance Sheet - COL'!D7:E7)/'Income Statement - COL'!E5*365 -> 4.6116109
A14: Liquidity Analysis
A15: Current Ratio | B15: Current Assets / Current Liabilities | C15: ='Balance Sheet - COL'!B12/'Balance Sheet - COL'!B30 -> 0.59013576 | D15: ='Balance Sheet - COL'!C12/'Balance Sheet - COL'!C30 -> 0.5847233 | E15: ='Balance Sheet - COL'!D12/'Balance Sheet - COL'!D30 -> 0.5855181 | F15: ='Balance Sheet - COL'!E12/'Balance Sheet - COL'!E30 -> 0.58868705
A16: Quick Ratio | B16: (Current Assets - Inventory - Prepayments) / Current Liabilities | C16: =('Balance Sheet - COL'!B12-'Balance Sheet - COL'!B9-'Balance Sheet - COL'!B8)/'Balance Sheet - COL'!B30 -> 0.21343874 | D16: =('Balance Sheet - COL'!C12-'Balance Sheet - COL'!C9-'Balance Sheet - COL'!C8)/'Balance Sheet - COL'!C30 -> 0.19017927 | E16: =('Balance Sheet - COL'!D12-'Balance Sheet - COL'!D9-'Balance Sheet - COL'!D8)/'Balance Sheet - COL'!D30 -> 0.21020599 | F16: =('Balance Sheet - COL'!E12-'Balance Sheet - COL'!E9-'Balance Sheet - COL'!E8)/'Balance Sheet - COL'!E30 -> 0.17442032
A17: Operating Cash Flow Ratio | B17: Cash Flow from Operating Activities / Current Liabilities | C17: ='Cash Flow Statement - COL'!B4/'Balance Sheet - COL'!B30 -> 0.48754081 | D17: ='Cash Flow Statement - COL'!C4/'Balance Sheet - COL'!C30 -> 0.4193297 | E17: ='Cash Flow Statement - COL'!D4/'Balance Sheet - COL'!D30 -> 0.43804619 | F17: ='Cash Flow Statement - COL'!E4/'Balance Sheet - COL'!E30 -> 0.41249446
A19: Capital Structure Ratios
A20: Debt to Equity (D/E) | B20: Total Liabilities / Total Equity | C20: ='Balance Sheet - COL'!B38/'Balance Sheet - COL'!B46 -> 5.442588 | D20: ='Balance Sheet - COL'!C38/'Balance Sheet - COL'!C46 -> 5.0294494 | E20: ='Balance Sheet - COL'!D38/'Balance Sheet - COL'!D46 -> 4.4505364 | F20: ='Balance Sheet - COL'!E38/'Balance Sheet - COL'!E46 -> 4.4935029
A21: Debt to Assets | B21: Total Liabilities / Total Assets | C21: ='Balance Sheet - COL'!B38/'Balance Sheet - COL'!B23 -> 0.84478287 | D21: ='Balance Sheet - COL'!C38/'Balance Sheet - COL'!C23 -> 0.83414738 | E21: ='Balance Sheet - COL'!D38/'Balance Sheet - COL'!D23 -> 0.81653182 | F21: ='Balance Sheet - COL'!E38/'Balance Sheet - COL'!E23 -> 0.81796678
A22: Equity Ratio | B22: Total Equity / Total Assets | C22: ='Balance Sheet - COL'!B44/'Balance Sheet - COL'!B23 -> 0.15521713 | D22: ='Balance Sheet - COL'!C44/'Balance Sheet - COL'!C23 -> 0.16585262 | E22: ='Balance Sheet - COL'!D44/'Balance Sheet - COL'!D23 -> 0.18346818 | F22: ='Balance Sheet - COL'!E44/'Balance Sheet - COL'!E23 -> 0.18203322
A23: Interest Coverage Ratio | B23: (Net Profit + Interest Expense + Tax Expense) / Interest Expense | C23: =('Income Statement - COL'!B25-SUM('Income Statement - COL'!B17:B18)-'Income Statement - COL'!B18)/SUM('Income Statement - COL'!B17:B18) -> 0.48910412 | D23: =('Income Statement - COL'!C25-SUM('Income Statement - COL'!C17:C18)-'Income Statement - COL'!C18)/SUM('Income Statement - COL'!C17:C18) -> 0.80738786 | E23: =('Income Statement - COL'!D25-SUM('Income Statement - COL'!D17:D18)-'Income Statement - COL'!D18)/SUM('Income Statement - COL'!D17:D18) -> 1.0350404 | F23: =('Income Statement - COL'!E25-SUM('Income Statement - COL'!E17:E18)-'Income Statement - COL'!E18)/SUM('Income Statement - COL'!E17:E18) -> 0.83698297
A24: Debt Coverage Ratio | B24: Non-current Liabilities / Cash Flow from Operating Activities | C24: ='Balance Sheet - COL'!B36/'Cash Flow Statement - COL'!B4 -> 3.3454353 | D24: ='Balance Sheet - COL'!C36/'Cash Flow Statement - COL'!C4 -> 3.4561338 | E24: ='Balance Sheet - COL'!D36/'Cash Flow Statement - COL'!D4 -> 3.038119 | F24: ='Balance Sheet - COL'!E36/'Cash Flow Statement - COL'!E4 -> 3.3949159
A26: Market Performance Analysis
A27: Earnings Per Share (EPS) | B27: Net Profit / Number of ordinary shares | C27: ='Income Statement - COL'!B25/('Market Cap - COL'!B2) -> 0.75342979 | D27: ='Income Statement - COL'!C25/('Market Cap - COL'!C2) -> 0.78437243 | E27: ='Income Statement - COL'!D25/('Market Cap - COL'!D2) -> 0.82038255 | F27: ='Income Statement - COL'!E25/('Market Cap - COL'!E2) -> 0.83470211
A28: Price to Earnings Ratio (PE) | B28: Current Share Price / Earnings Per Share | C28: ='Market Cap - COL'!B3/'Ratio Analysis - COL'!C27 -> 22.337848 | D28: ='Market Cap - COL'!C3/'Ratio Analysis - COL'!D27 -> 22.706051 | E28: ='Market Cap - COL'!D3/'Ratio Analysis - COL'!E27 -> 22.428561 | F28: ='Market Cap - COL'!E3/'Ratio Analysis - COL'!F27 -> 20.402488
A29: Market to Book Ratio (M/B) | B29: Current Market Capitalisation / Net Assets | C29: =('Market Cap - COL'!B4)/'Balance Sheet - COL'!B44 -> 7.9806388 | D29: =('Market Cap - COL'!C4)/'Balance Sheet - COL'!C44 -> 7.6171386 | E29: =('Market Cap - COL'!D4)/'Balance Sheet - COL'!D44 -> 7.3380691 | F29: =('Market Cap - COL'!E4)/'Balance Sheet - COL'!E44 -> 6.3063262
A31: DuPont Analysis | B31: ROE = PM * ATO * Leverage
A32: Profit Margin (PM) | B32: Net Profit / Sales Revenue | C32: ='Income Statement - COL'!B25/'Income Statement - COL'!B5 -> 0.026061926 | D32: ='Income Statement - COL'!C25/'Income Statement - COL'!C5 -> 0.026619929 | E32: ='Income Statement - COL'!D25/'Income Statement - COL'!D5 -> 0.027122496 | F32: ='Income Statement - COL'!E25/'Income Statement - COL'!E5 -> 0.025659269
A33: Asset Turnover Ratio (ATO) | B33: Sales Revenue / Average Total Assets | D33: ='Income Statement - COL'!C5/AVERAGE('Balance Sheet - COL'!B23:C23) -> 2.1304148 | E33: ='Income Statement - COL'!D5/AVERAGE('Balance Sheet - COL'!C23:D23) -> 2.1807261 | F33: ='Income Statement - COL'!E5/AVERAGE('Balance Sheet - COL'!D23:E23) -> 2.2834757
A34: Leverage | B34: Average Total Assets / Average Equity | D34: =AVERAGE('Balance Sheet - COL'!B23:C23)/AVERAGE('Balance Sheet - COL'!B44:C44) -> 6.2251979 | E34: =AVERAGE('Balance Sheet - COL'!C23:D23)/AVERAGE('Balance Sheet - COL'!C44:D44) -> 5.7296296 | F34: =AVERAGE('Balance Sheet - COL'!D23:E23)/AVERAGE('Balance Sheet - COL'!D44:E44) -> 5.4728237
A35: Return on Equity (ROE) | B35: ROE = PM * ATO * Leverage | D35: =D32*D33*D34 -> 0.35304026 | E35: =E32*E33*E34 -> 0.33888889 | F35: =F32*F33*F34 -> 0.32066542

Sheet Ratio Analysis - WOW
C1: Woolworths Group Limited Ratio Analysis
H2: Notes:
A3: Profitability Ratios | B3: Formula | C3: 2021 | D3: 2022 | E3: 2023 | F3: 2024
A4: Return on Equity (ROE) | B4: Net Profit / Average Equity | D4: ='Income Statement - WOW'!C25/AVERAGE('Balance Sheet - WOW'!$B$47:$C$47) -> 0.39704195 | E4: ='Income Statement - WOW'!D25/AVERAGE('Balance Sheet - WOW'!$C$47:$D$47) -> 0.25716315 | F4: ='Income Statement - WOW'!E25/AVERAGE('Balance Sheet - WOW'!$D$47:$E$47) -> 0.019283066
A5: Return on Assets (ROA) | B5: Net Profit / Average Total Assets | D5: ='Income Statement - WOW'!C25/AVERAGE(('Balance Sheet - WOW'!C25),('Balance Sheet - WOW'!B32)) -> 0.055222557 | E5: ='Income Statement - WOW'!D25/AVERAGE(('Balance Sheet - WOW'!D25),('Balance Sheet - WOW'!C32)) -> 0.073381684 | F5: ='Income Statement - WOW'!E25/AVERAGE(('Balance Sheet - WOW'!E25),('Balance Sheet - WOW'!D32)) -> 0.0051067173
A6: Profit Margin (PM) | B6: Net Profit / Sales Revenue | C6: ='Income Statement - WOW'!B25/'Income Statement - WOW'!B5 -> 0.02883614 | D6: ='Income Statement - WOW'!C25/'Income Statement - WOW'!C5 -> 0.025587931 | E6: ='Income Statement - WOW'!D25/'Income Statement - WOW'!D5 -> 0.025336734 | F6: ='Income Statement - WOW'!E25/'Income Statement - WOW'!E5 -> 0.0017225641
A7: Cash Flow Margin | B7: Cash Flow from Operating Activities / Sales Revenue | C7: ='Cash Flow Statement - WOW'!B4/'Income Statement - WOW'!B5 -> 0.083025101 | D7: ='Cash Flow Statement - WOW'!C4/'Income Statement - WOW'!C5 -> 0.05551447 | E7: ='Cash Flow Statement - WOW'!D4/'Income Statement - WOW'!D5 -> 0.073941581 | F7: ='Cash Flow Statement - WOW'!E4/'Income Statement - WOW'!E5 -> 0.064176555
A9: Efficiency Ratios
A10: Asset Turnover Ratio (ATO) | B10: Sales Revenue / Average Total Assets | D10: ='Income Statement - WOW'!C5/AVERAGE('Balance Sheet - WOW'!B25:C25) -> 1.6783848 | E10: ='Income Statement - WOW'!D5/AVERAGE('Balance Sheet - WOW'!C25:D25) -> 1.9214895 | F10: ='Income Statement - WOW'!E5/AVERAGE('Balance Sheet - WOW'!D25:E25) -> 2.0100024
A11: Days Inventory | B11: Average Inventory / Cost of Sales * 365 days | D11: =AVERAGE('Balance Sheet - WOW'!B9:C9)/SUM('Income Statement - WOW'!C9)*365 -> 27.347754 | E11: =AVERAGE('Balance Sheet - WOW'!C9:D9)/SUM('Income Statement - WOW'!D9)*365 -> 28.239898 | F11: =AVERAGE('Balance Sheet - WOW'!D9:E9)/SUM('Income Statement - WOW'!E9)*365 -> 29.147509
A12: Days in Receivables | B12: Average Accounts Receivable / Sales Revenue * 365 days | D12: =AVERAGE('Balance Sheet - WOW'!B7:C7)/'Income Statement - WOW'!C5*365 -> 4.0069681 | E12: =AVERAGE('Balance Sheet - WOW'!C7:D7)/'Income Statement - WOW'!D5*365 -> 5.3137151 | F12: =AVERAGE('Balance Sheet - WOW'!D7:E7)/'Income Statement - WOW'!E5*365 -> 5.7016136
A14: Liquidity Analysis
A15: Current Ratio | B15: Current Assets / Current Liabilities | C15: ='Balance Sheet - WOW'!B13/'Balance Sheet - WOW'!B32 -> 0.68287408 | D15: ='Balance Sheet - WOW'!C13/'Balance Sheet - WOW'!C32 -> 0.56837209 | E15: ='Balance Sheet - WOW'!D13/'Balance Sheet - WOW'!D32 -> 0.53634528 | F15: ='Balance Sheet - WOW'!E13/'Balance Sheet - WOW'!E32 -> 0.54536235
A16: Quick Ratio | B16: (Current Assets - Inventory - Prepayments) / Current Liabilities | C16: =('Balance Sheet - WOW'!B13-'Balance Sheet - WOW'!B9-'Balance Sheet - WOW'!B8)/'Balance Sheet - WOW'!B32 -> 0.54007873 | D16: =('Balance Sheet - WOW'!C13-'Balance Sheet - WOW'!C9-'Balance Sheet - WOW'!C8)/'Balance Sheet - WOW'!C32 -> 0.21665116 | E16: =('Balance Sheet - WOW'!D13-'Balance Sheet - WOW'!D9-'Balance Sheet - WOW'!D8)/'Balance Sheet - WOW'!D32 -> 0.22522295 | F16: =('Balance Sheet - WOW'!E13-'Balance Sheet - WOW'!E9-'Balance Sheet - WOW'!E8)/'Balance Sheet - WOW'!E32 -> 0.20656838
A17: Operating Cash Flow Ratio | B17: Cash Flow from Operating Activities / Current Liabilities | C17: ='Cash Flow Statement - WOW'!B4/'Balance Sheet - WOW'!B32 -> 0.20002595 | D17: ='Cash Flow Statement - WOW'!C4/'Balance Sheet - WOW'!C32 -> 0.31423256 | E17: ='Cash Flow Statement - WOW'!D4/'Balance Sheet - WOW'!D32 -> 0.39996635 | F17: ='Cash Flow Statement - WOW'!E4/'Balance Sheet - WOW'!E32 -> 0.34004212
A19: Capital Structure Ratios
A20: Debt to Equity (D/E) | B20: Total Liabilities / Total Equity | C20: ='Balance Sheet - WOW'!B40/'Balance Sheet - WOW'!B47 -> 21.562392 | D20: ='Balance Sheet - WOW'!C40/'Balance Sheet - WOW'!C47 -> 4.4510157 | E20: ='Balance Sheet - WOW'!D40/'Balance Sheet - WOW'!D47 -> 4.1253618 | F20: ='Balance Sheet - WOW'!E40/'Balance Sheet - WOW'!E47 -> 5.0926391
A21: Debt to Assets | B21: Total Liabilities / Total Assets | C21: ='Balance Sheet - WOW'!B40/'Balance Sheet - WOW'!B25 -> 0.95567846 | D21: ='Balance Sheet - WOW'!C40/'Balance Sheet - WOW'!C25 -> 0.81654795 | E21: ='Balance Sheet - WOW'!D40/'Balance Sheet - WOW'!D25 -> 0.80489182 | F21: ='Balance Sheet - WOW'!E40/'Balance Sheet - WOW'!E25 -> 0.83586752
A22: Equity Ratio | B22: Total Equity / Total Assets | C22: ='Balance Sheet - WOW'!B47/'Balance Sheet - WOW'!B25 -> 0.044321541 | D22: ='Balance Sheet - WOW'!C47/'Balance Sheet - WOW'!C25 -> 0.18345205 | E22: ='Balance Sheet - WOW'!D47/'Balance Sheet - WOW'!D25 -> 0.19510818 | F22: ='Balance Sheet - WOW'!E47/'Balance Sheet - WOW'!E25 -> 0.16413248
A23: Interest Coverage Ratio | B23: (Net Profit + Interest Expense + Tax Expense) / Interest Expense | C23: =('Income Statement - WOW'!B25-SUM('Income Statement - WOW'!B17:B18)-'Income Statement - WOW'!B24)/SUM('Income Statement - WOW'!B17:B18) -> 0.59047619 | D23: =('Income Statement - WOW'!C25-SUM('Income Statement - WOW'!C17:C18)-'Income Statement - WOW'!C24)/SUM('Income Statement - WOW'!C17:C18) -> 0.61867089 | E23: =('Income Statement - WOW'!D25-SUM('Income Statement - WOW'!D17:D18)-'Income Statement - WOW'!D24)/SUM('Income Statement - WOW'!D17:D18) -> 0.2892562 | F23: =('Income Statement - WOW'!E25-SUM('Income Statement - WOW'!E17:E18)-'Income Statement - WOW'!E24)/SUM('Income Statement - WOW'!E17:E18) -> -1.7906404
A24: Debt Coverage Ratio | B24: Non-current Liabilities / Cash Flow from Operating Activities | C24: ='Balance Sheet - WOW'!B38/'Cash Flow Statement - WOW'!B4 -> 3.1098616 | D24: ='Balance Sheet - WOW'!C38/'Cash Flow Statement - WOW'!C4 -> 4.8605684 | E24: ='Balance Sheet - WOW'!D38/'Cash Flow Statement - WOW'!D4 -> 3.1966765 | F24: ='Balance Sheet - WOW'!E38/'Cash Flow Statement - WOW'!E4 -> 3.5666437
A26: Market Performance Analysis
A27: Earnings Per Share (EPS) | B27: Net Profit / Number of ordinary shares | C27: ='Income Statement - WOW'!B25/('Market Cap - WOW'!B2) -> 1.2668612 | D27: ='Income Statement - WOW'!C25/('Market Cap - WOW'!C2) -> 1.2826427 | E27: ='Income Statement - WOW'!D25/('Market Cap - WOW'!D2) -> 1.3366702 | F27: ='Income Statement - WOW'!E25/('Market Cap - WOW'!E2) -> 0.095776031
A28: Price to Earnings Ratio (PE) | B28: Current Share Price / Earnings Per Share | C28: ='Market Cap - WOW'!B3/'Ratio Analysis - WOW'!C27 -> 33.847432 | D28: ='Market Cap - WOW'!C3/'Ratio Analysis - WOW'!D27 -> 27.646046 | E28: ='Market Cap - WOW'!D3/'Ratio Analysis - WOW'!E27 -> 29.82037 | F28: ='Market Cap - WOW'!E3/'Ratio Analysis - WOW'!F27 -> 352.80226
A29: Market to Book Ratio (M/B) | B29: Current Market Capitalisation / Net Assets | C29: =('Market Cap - WOW'!B4)/'Balance Sheet - WOW'!B47 -> 31.258756 | D29: =('Market Cap - WOW'!C4)/'Balance Sheet - WOW'!C47 -> 7.0519158 | E29: =('Market Cap - WOW'!D4)/'Balance Sheet - WOW'!D47 -> 7.3994489 | F29: =('Market Cap - WOW'!E4)/'Balance Sheet - WOW'!E47 -> 7.4107476
A31: DuPont Analysis | B31: ROE = PM * ATO * Leverage
A32: Profit Margin (PM) | B32: Net Profit / Sales Revenue | C32: ='Income Statement - WOW'!B25/'Income Statement - WOW'!B5 -> 0.02883614 | D32: ='Income Statement - WOW'!C25/'Income Statement - WOW'!C5 -> 0.025587931 | E32: ='Income Statement - WOW'!D25/'Income Statement - WOW'!D5 -> 0.025336734 | F32: ='Income Statement - WOW'!E25/'Income Statement - WOW'!E5 -> 0.0017225641
A33: Asset Turnover Ratio (ATO) | B33: Sales Revenue / Average Total Assets | D33: ='Income Statement - WOW'!C5/AVERAGE('Balance Sheet - WOW'!B25:C25) -> 1.6783848 | E33: ='Income Statement - WOW'!D5/AVERAGE('Balance Sheet - WOW'!C25:D25) -> 1.9214895 | F33: ='Income Statement - WOW'!E5/AVERAGE('Balance Sheet - WOW'!D25:E25) -> 2.0100024
A34: Leverage | B34: Average Total Assets / Average Equity | D34: =AVERAGE('Balance Sheet - WOW'!B25:C25)/AVERAGE('Balance Sheet - WOW'!B47:C47) -> 9.2450593 | E34: =AVERAGE('Balance Sheet - WOW'!C25:D25)/AVERAGE('Balance Sheet - WOW'!C47:D47) -> 5.2822638 | F34: =AVERAGE('Balance Sheet - WOW'!D25:E25)/AVERAGE('Balance Sheet - WOW'!D47:E47) -> 5.5693449
A35: Return on Equity (ROE) | D35: =D32*D33*D34 -> 0.39704195 | E35: =E32*E33*E34 -> 0.25716315 | F35: =F32*F33*F34 -> 0.019283066

Sheet Graph
A2: Variables | B2: 2021 | C2: 2022 | D2: 2023 | E2: 2024 | F2: 2024 % Change
A3: Coles Net Profit | B3: 1005000000 | C3: 1048000000 | D3: 1098000000 | E3: 1118000000 | F3: =(E3-D3)/D3 -> 0.018214936
A4: Woolworths Net Profit | B4: 1606000000 | C4: 1557000000 | D4: 1629000000 | E4: 117000000 | F4: =(E4-D4)/D4 -> -0.9281768
A5: Coles Equity | B5: 2813000000 | C5: 3124000000 | D5: 3356000000 | E5: 3617000000 | F5: =(E5-D5)/D5 -> 0.077771156
A6: Woolworths Equity | B6: 1739000000 | C6: 6104000000 | D6: 6565000000 | E6: 5570000000 | F6: =(E6-D6)/D6 -> -0.15156131
A7: Ratio | B7: 2021 | C7: 2022 | D7: 2023 | E7: 2024 | F7: =(E7-D7)/D7 -> 0.00049431537
A8: Coles ROE | C8: 0.353 | D8: 0.3389 | E8: 0.3207 | F8: =E8-D8 -> -0.0182
A9: Woolworth ROE | C9: 0.397 | D9: 0.2572 | E9: 0.0193 | F9: =E9-D9 -> -0.2379
A12: Variables | B12: 2021 | C12: 2022 | D12: 2023 | E12: 2024 | F12: 2024 % Change
A13: Coles Net Profit | B13: 1005000000 | C13: 1048000000 | D13: 1098000000 | E13: 1118000000 | F13: =(E13-D13)/D13 -> 0.018214936
A14: Woolworths Net Profit | B14: 1606000000 | C14: 1557000000 | D14: 1629000000 | E14: 117000000 | F14: =(E14-D14)/D14 -> -0.9281768
