Workbook

Sheet Output_pathworths & R2
A1: Option | B1: Intercept | C1: 450 | D1: 550 | E1: Indoor2_Smart Adaptive Display | F1: Indoor3_AI-Optimized Vision | G1: Outdoor2_Advanced GPS & Live Mapping | H1: Outdoor3_AR Navigation & Real-Time Environmental Data | I1: Professional2_Smart Voice Commands & Reminders | J1: Professional3_AI Assistant & Hands-Free Control | K1: Fitness2_Heart Rate & Workout Insights | L1: R_squared
A2: 1 | B2: 7.1666667 | C2: 2.3333333 | D2: 0.33333333 | E2: -0.16666667 | F2: -1 | G2: -0.66666667 | H2: -9.7414327e-16 | I2: -1.1666667 | J2: -1.3333333 | K2: -1.3333333 | L2: 0.97587719
A3: 2 | B3: 5.6666667 | C3: 3.3333333 | D3: 2.3333333 | E3: 1.3333333 | F3: -1.5 | G3: -2.6666667 | H3: -4.5 | I3: 0.83333333 | J3: 0.66666667 | K3: -3.8333333 | L3: 0.97505669
A4: 3 | B4: 5 | C4: 0 | D4: 0 | E4: 0 | F4: 0 | G4: 0 | H4: 0 | I4: 0 | J4: 0 | K4: 0 | L4: 1
A5: 5 | B5: 5.8333333 | C5: 3.6666667 | D5: 3.6666667 | E5: 1.1666667 | F5: -2.5 | G5: -2.3333333 | H5: -2.5 | I5: -0.33333333 | J5: 0.33333333 | K5: -2.1666667 | L5: 0.99003623
A6: 6 | B6: 1.1666667 | C6: -1.6666667 | D6: -0.66666667 | E6: -0.16666667 | F6: 1 | G6: 2.3333333 | H6: 2 | I6: 0.83333333 | J6: 0.66666667 | K6: 0.66666667 | L6: 0.74250936
A7: 7 | B7: 4.1666667 | C7: -0.66666667 | D7: -1.6666667 | E7: 0.83333333 | F7: 4 | G7: -0.66666667 | H7: 1 | I7: -1.1666667 | J7: -0.33333333 | K7: -0.33333333 | L7: 0.9962585
A8: 8 | B8: 5.5 | C8: 2 | D8: 2 | E8: -0.5 | F8: -2.5 | G8: -1 | H8: -0.5 | I8: 2.5330249e-16 | J8: 1 | K8: -1.5 | L8: 0.85
A9: 9 | B9: 4.6666667 | C9: 0.33333333 | D9: 2.3333333 | E9: 2.3333333 | F9: 1.5 | G9: -0.66666667 | H9: -3.5 | I9: 0.83333333 | J9: -0.33333333 | K9: -2.8333333 | L9: 0.96474359
A10: 10 | B10: 2.3333333 | C10: -1.3333333 | D10: 1.1666667 | E10: 3.6666667 | F10: 2 | G10: -2.8333333 | H10: -4 | I10: 1.6666667 | J10: 2.8333333 | K10: 0.83333333 | L10: 0.92739274
A11: 11 | B11: 5.8333333 | C11: -0.33333333 | D11: -0.83333333 | E11: -0.83333333 | F11: 0.5 | G11: 1.1666667 | H11: 1.5 | I11: 0.66666667 | J11: -0.16666667 | K11: 0.33333333 | L11: 0.96014493
A12: 13 | B12: 1.1666667 | C12: 3.3333333 | D12: 5.3333333 | E12: 4.8333333 | F12: 2.5 | G12: -2.6666667 | H12: -4.5 | I12: 2.3333333 | J12: 0.66666667 | K12: -1.8333333 | L12: 0.99444444
A13: 14 | B13: 6.6666667 | C13: -0.66666667 | D13: -3.1666667 | E13: -1.6666667 | F13: 1.5 | G13: -0.16666667 | H13: 3.5 | I13: -1.1666667 | J13: -2.8333333 | K13: -1.3333333 | L13: 0.98671498
... A44: 67 | B44: 4.8333333 | C44: -0.33333333 | D44: -1.8333333 | E44: -2.8333333 | F44: -2 | G44: 2.1666667 | H44: 4 | I44: -0.83333333 | J44: -0.16666667 | K44: 0.83333333 | L44: 0.98882114

Sheet Report Part1 >>

Sheet T1_Avg. Part-Worth
A1: Option | B1: Intercept | C1: 450 | D1: 550 | E1: Indoor2_Smart Adaptive Display | F1: Indoor3_AI-Optimized Vision | G1: Outdoor2_Advanced GPS & Live Mapping | H1: Outdoor3_AR Navigation & Real-Time Environmental Data | I1: Professional2_Smart Voice Commands & Reminders | J1: Professional3_AI Assistant & Hands-Free Control | K1: Fitness2_Heart Rate & Workout Insights | L1: R_squared
A2: 1 | B2: 7.1666667 | C2: 2.3333333 | D2: 0.33333333 | E2: -0.16666667 | F2: -1 | G2: -0.66666667 | H2: -9.7414327e-16 | I2: -1.1666667 | J2: -1.3333333 | K2: -1.3333333 | L2: 0.97587719
A3: 2 | B3: 5.6666667 | C3: 3.3333333 | D3: 2.3333333 | E3: 1.3333333 | F3: -1.5 | G3: -2.6666667 | H3: -4.5 | I3: 0.83333333 | J3: 0.66666667 | K3: -3.8333333 | L3: 0.97505669
A4: 3 | B4: 5 | C4: 0 | D4: 0 | E4: 0 | F4: 0 | G4: 0 | H4: 0 | I4: 0 | J4: 0 | K4: 0 | L4: 1
A5: 5 | B5: 5.8333333 | C5: 3.6666667 | D5: 3.6666667 | E5: 1.1666667 | F5: -2.5 | G5: -2.3333333 | H5: -2.5 | I5: -0.33333333 | J5: 0.33333333 | K5: -2.1666667 | L5: 0.99003623
A6: 6 | B6: 1.1666667 | C6: -1.6666667 | D6: -0.66666667 | E6: -0.16666667 | F6: 1 | G6: 2.3333333 | H6: 2 | I6: 0.83333333 | J6: 0.66666667 | K6: 0.66666667 | L6: 0.74250936
A7: 7 | B7: 4.1666667 | C7: -0.66666667 | D7: -1.6666667 | E7: 0.83333333 | F7: 4 | G7: -0.66666667 | H7: 1 | I7: -1.1666667 | J7: -0.33333333 | K7: -0.33333333 | L7: 0.9962585
A8: 8 | B8: 5.5 | C8: 2 | D8: 2 | E8: -0.5 | F8: -2.5 | G8: -1 | H8: -0.5 | I8: 2.5330249e-16 | J8: 1 | K8: -1.5 | L8: 0.85
A9: 9 | B9: 4.6666667 | C9: 0.33333333 | D9: 2.3333333 | E9: 2.3333333 | F9: 1.5 | G9: -0.66666667 | H9: -3.5 | I9: 0.83333333 | J9: -0.33333333 | K9: -2.8333333 | L9: 0.96474359
A10: 10 | B10: 2.3333333 | C10: -1.3333333 | D10: 1.1666667 | E10: 3.6666667 | F10: 2 | G10: -2.8333333 | H10: -4 | I10: 1.6666667 | J10: 2.8333333 | K10: 0.83333333 | L10: 0.92739274
A11: 11 | B11: 5.8333333 | C11: -0.33333333 | D11: -0.83333333 | E11: -0.83333333 | F11: 0.5 | G11: 1.1666667 | H11: 1.5 | I11: 0.66666667 | J11: -0.16666667 | K11: 0.33333333 | L11: 0.96014493
A12: 13 | B12: 1.1666667 | C12: 3.3333333 | D12: 5.3333333 | E12: 4.8333333 | F12: 2.5 | G12: -2.6666667 | H12: -4.5 | I12: 2.3333333 | J12: 0.66666667 | K12: -1.8333333 | L12: 0.99444444
A13: 14 | B13: 6.6666667 | C13: -0.66666667 | D13: -3.1666667 | E13: -1.6666667 | F13: 1.5 | G13: -0.16666667 | H13: 3.5 | I13: -1.1666667 | J13: -2.8333333 | K13: -1.3333333 | L13: 0.98671498
... A44: 67 | B44: 4.8333333 | C44: -0.33333333 | D44: -1.8333333 | E44: -2.8333333 | F44: -2 | G44: 2.1666667 | H44: 4 | I44: -0.83333333 | J44: -0.16666667 | K44: 0.83333333 | L44: 0.98882114
A45: Mean | B45: =AVERAGE(B2:B44) -> 4.3410853 | C45: =AVERAGE(C2:C44) -> 0.47286822 | D45: =AVERAGE(D2:D44) -> 0.13565891 | E45: =AVERAGE(E2:E44) -> -0.20155039 | F45: =AVERAGE(F2:F44) -> -0.26744186 | G45: =AVERAGE(G2:G44) -> 0.25193798 | H45: =AVERAGE(H2:H44) -> 0.034883721 | I45: =AVERAGE(I2:I44) -> 0.22868217 | ... L45: =AVERAGE(L2:L44) -> 0.95589134
B48: Attribute | C48: Level | D48: Average Part-Worth Utility
B49: Price | C49: Price $450 | D49: =C45 -> 0.47286822 | F49: Average R-Square
B50: Price | C50: Price $550 | D50: =D45 -> 0.13565891 | F50: =L45 -> 0.95589134
B51: Indoor | C51: Smart Adaptive Display | D51: =E45 -> -0.20155039
B52: Indoor | C52: AI-Optimized Vision | D52: =F45 -> -0.26744186
B53: Outdoor | C53: Advanced GPS & Live Mapping | D53: =G45 -> 0.25193798
B54: Outdoor | C54: AR Navigation & Real-Time Environmental Data | D54: =H45 -> 0.034883721
B55: Professional | C55: Smart Voice Commands & Reminders | D55: =I45 -> 0.22868217
B56: Professional | C56: AI Assistant & Hands-Free Control | D56: =J45 -> 0.44573643
B57: Health&Fitness | C57: Heart Rate & Workout Insights | D57: =K45 -> -0.17054264

Sheet T2_Relative Importance Anal
A1: Option | B1: Intercept | C1: 450 | D1: 550 | E1: Indoor2_Smart Adaptive Display | F1: Indoor3_AI-Optimized Vision | G1: Outdoor2_Advanced GPS & Live Mapping | H1: Outdoor3_AR Navigation & Real-Time Environmental Data | I1: Professional2_Smart Voice Commands & Reminders | J1: Professional3_AI Assistant & Hands-Free Control | K1: Fitness2_Heart Rate & Workout Insights | L1: R_squared
A2: 1 | B2: 7.166667 | C2: 2.333333 | D2: 0.333333 | E2: -0.16667 | F2: -1 | G2: -0.66667 | H2: -9.7e-16 | I2: -1.16667 | J2: -1.33333 | K2: -1.33333 | L2: 0.975877
A3: 2 | B3: 5.666667 | C3: 3.333333 | D3: 2.333333 | E3: 1.333333 | F3: -1.5 | G3: -2.66667 | H3: -4.5 | I3: 0.833333 | J3: 0.666667 | K3: -3.83333 | L3: 0.975057
A4: 3 | B4: 5 | C4: 0 | D4: 0 | E4: 0 | F4: 0 | G4: 0 | H4: 0 | I4: 0 | J4: 0 | K4: 0 | L4: 1
A5: 5 | B5: 5.833333 | C5: 3.666667 | D5: 3.666667 | E5: 1.166667 | F5: -2.5 | G5: -2.33333 | H5: -2.5 | I5: -0.33333 | J5: 0.333333 | K5: -2.16667 | L5: 0.990036
A6: 6 | B6: 1.166667 | C6: -1.66667 | D6: -0.66667 | E6: -0.16667 | F6: 1 | G6: 2.333333 | H6: 2 | I6: 0.833333 | J6: 0.666667 | K6: 0.666667 | L6: 0.742509
A7: 7 | B7: 4.166667 | C7: -0.66667 | D7: -1.66667 | E7: 0.833333 | F7: 4 | G7: -0.66667 | H7: 1 | I7: -1.16667 | J7: -0.33333 | K7: -0.33333 | L7: 0.996259
A8: 8 | B8: 5.5 | C8: 2 | D8: 2 | E8: -0.5 | F8: -2.5 | G8: -1 | H8: -0.5 | I8: 2.53e-16 | J8: 1 | K8: -1.5 | L8: 0.85
A9: 9 | B9: 4.666667 | C9: 0.333333 | D9: 2.333333 | E9: 2.333333 | F9: 1.5 | G9: -0.66667 | H9: -3.5 | I9: 0.833333 | J9: -0.33333 | K9: -2.83333 | L9: 0.964744
A10: 10 | B10: 2.333333 | C10: -1.33333 | D10: 1.166667 | E10: 3.666667 | F10: 2 | G10: -2.83333 | H10: -4 | I10: 1.666667 | J10: 2.833333 | K10: 0.833333 | L10: 0.927393
A11: 11 | B11: 5.833333 | C11: -0.33333 | D11: -0.83333 | E11: -0.83333 | F11: 0.5 | G11: 1.166667 | H11: 1.5 | I11: 0.666667 | J11: -0.16667 | K11: 0.333333 | L11: 0.960145
A12: 13 | B12: 1.166667 | C12: 3.333333 | D12: 5.333333 | E12: 4.833333 | F12: 2.5 | G12: -2.66667 | H12: -4.5 | I12: 2.333333 | J12: 0.666667 | K12: -1.83333 | L12: 0.994444
A13: 14 | B13: 6.666667 | C13: -0.66667 | D13: -3.16667 | E13: -1.66667 | F13: 1.5 | G13: -0.16667 | H13: 3.5 | I13: -1.16667 | J13: -2.83333 | K13: -1.33333 | L13: 0.986715
... A44: 67 | B44: 4.833333 | C44: -0.33333 | D44: -1.83333 | E44: -2.83333 | F44: -2 | G44: 2.166667 | H44: 4 | I44: -0.83333 | J44: -0.16667 | K44: 0.833333 | L44: 0.988821
A45: Mean | B45: =AVERAGE(B2:B44) -> 4.3410853 | C45: =AVERAGE(C2:C44) -> 0.47286849 | D45: =AVERAGE(D2:D44) -> 0.13565891 | E45: =AVERAGE(E2:E44) -> -0.20155033 | F45: =AVERAGE(F2:F44) -> -0.26744186 | G45: =AVERAGE(G2:G44) -> 0.25193798 | H45: =AVERAGE(H2:H44) -> 0.034883721 | I45: =AVERAGE(I2:I44) -> 0.22868181 | ... L45: =AVERAGE(L2:L44) -> 0.95589137
A48: Option | B48: Price | C48: Indoor | D48: Outdoor | E48: Professional | F48: Health&Fitness
A49: 1 | B49: =MAX(C2:D2)-MIN(C2:D2) -> 2 | C49: =MAX(E2:F2)-MIN(E2:F2) -> 0.83333 | D49: =MAX(G2:H2)-MIN(G2:H2) -> 0.66667 | E49: =MAX(I2:J2)-MIN(I2:J2) -> 0.16666 | F49: =ABS(L2) -> 0.975877
A50: 2 | B50: =MAX(C3:D3)-MIN(C3:D3) -> 1 | C50: =MAX(E3:F3)-MIN(E3:F3) -> 2.833333 | D50: =MAX(G3:H3)-MIN(G3:H3) -> 1.83333 | E50: =MAX(I3:J3)-MIN(I3:J3) -> 0.166666 | F50: =ABS(L3) -> 0.975057
A51: 3 | B51: =MAX(C4:D4)-MIN(C4:D4) -> 0 | C51: =MAX(E4:F4)-MIN(E4:F4) -> 0 | D51: =MAX(G4:H4)-MIN(G4:H4) -> 0 | E51: =MAX(I4:J4)-MIN(I4:J4) -> 0 | F51: =ABS(L4) -> 1
A52: 5 | B52: =MAX(C5:D5)-MIN(C5:D5) -> 0 | C52: =MAX(E5:F5)-MIN(E5:F5) -> 3.666667 | D52: =MAX(G5:H5)-MIN(G5:H5) -> 0.16667 | E52: =MAX(I5:J5)-MIN(I5:J5) -> 0.666663 | F52: =ABS(L5) -> 0.990036
A53: 6 | B53: =MAX(C6:D6)-MIN(C6:D6) -> 1 | C53: =MAX(E6:F6)-MIN(E6:F6) -> 1.16667 | D53: =MAX(G6:H6)-MIN(G6:H6) -> 0.333333 | E53: =MAX(I6:J6)-MIN(I6:J6) -> 0.166666 | F53: =ABS(L6) -> 0.742509
A54: 7 | B54: =MAX(C7:D7)-MIN(C7:D7) -> 1 | C54: =MAX(E7:F7)-MIN(E7:F7) -> 3.166667 | D54: =MAX(G7:H7)-MIN(G7:H7) -> 1.66667 | E54: =MAX(I7:J7)-MIN(I7:J7) -> 0.83334 | F54: =ABS(L7) -> 0.996259
A55: 8 | B55: =MAX(C8:D8)-MIN(C8:D8) -> 0 | C55: =MAX(E8:F8)-MIN(E8:F8) -> 2 | D55: =MAX(G8:H8)-MIN(G8:H8) -> 0.5 | E55: =MAX(I8:J8)-MIN(I8:J8) -> 1 | F55: =ABS(L8) -> 0.85
A56: 9 | B56: =MAX(C9:D9)-MIN(C9:D9) -> 2 | C56: =MAX(E9:F9)-MIN(E9:F9) -> 0.833333 | D56: =MAX(G9:H9)-MIN(G9:H9) -> 2.83333 | E56: =MAX(I9:J9)-MIN(I9:J9) -> 1.166663 | F56: =ABS(L9) -> 0.964744
A57: 10 | B57: =MAX(C10:D10)-MIN(C10:D10) -> 2.499997 | C57: =MAX(E10:F10)-MIN(E10:F10) -> 1.666667 | D57: =MAX(G10:H10)-MIN(G10:H10) -> 1.16667 | E57: =MAX(I10:J10)-MIN(I10:J10) -> 1.166666 | F57: =ABS(L10) -> 0.927393
A58: 11 | B58: =MAX(C11:D11)-MIN(C11:D11) -> 0.5 | C58: =MAX(E11:F11)-MIN(E11:F11) -> 1.33333 | D58: =MAX(G11:H11)-MIN(G11:H11) -> 0.333333 | E58: =MAX(I11:J11)-MIN(I11:J11) -> 0.833337 | F58: =ABS(L11) -> 0.960145
A59: 13 | B59: =MAX(C12:D12)-MIN(C12:D12) -> 2 | C59: =MAX(E12:F12)-MIN(E12:F12) -> 2.333333 | D59: =MAX(G12:H12)-MIN(G12:H12) -> 1.83333 | E59: =MAX(I12:J12)-MIN(I12:J12) -> 1.666666 | F59: =ABS(L12) -> 0.994444
A60: 14 | B60: =MAX(C13:D13)-MIN(C13:D13) -> 2.5 | C60: =MAX(E13:F13)-MIN(E13:F13) -> 3.16667 | D60: =MAX(G13:H13)-MIN(G13:H13) -> 3.66667 | E60: =MAX(I13:J13)-MIN(I13:J13) -> 1.66666 | F60: =ABS(L13) -> 0.986715
... A91: 67 | B91: =MAX(C44:D44)-MIN(C44:D44) -> 1.5 | C91: =MAX(E44:F44)-MIN(E44:F44) -> 0.83333 | D91: =MAX(G44:H44)-MIN(G44:H44) -> 1.833333 | E91: =MAX(I44:J44)-MIN(I44:J44) -> 0.66666 | F91: =ABS(L44) -> 0.988821
A93: Option | B93: Price | C93: Indoor | D93: Outdoor | E93: Professional | F93: Health&Fitness
A94: 1 | B94: =B49/SUM($B49:$F49) -> 0.43079894 | C94: =C49/SUM($B49:$F49) -> 0.17949884 | D94: =D49/SUM($B49:$F49) -> 0.14360036 | E94: =E49/SUM($B49:$F49) -> 0.035898475 | F94: =F49/SUM($B49:$F49) -> 0.21020339
A95: 2 | B95: =B50/SUM($B50:$F50) -> 0.14687769 | C95: =C50/SUM($B50:$F50) -> 0.4161534 | D95: =D50/SUM($B50:$F50) -> 0.26927527 | E95: =E50/SUM($B50:$F50) -> 0.024479517 | F95: =F50/SUM($B50:$F50) -> 0.14321412
A96: 3 | B96: =B51/SUM($B51:$F51) -> 0 | C96: =C51/SUM($B51:$F51) -> 0 | D96: =D51/SUM($B51:$F51) -> 0 | E96: =E51/SUM($B51:$F51) -> 0 | F96: =F51/SUM($B51:$F51) -> 1
A97: 5 | B97: =B52/SUM($B52:$F52) -> 0 | C97: =C52/SUM($B52:$F52) -> 0.66787668 | D97: =D52/SUM($B52:$F52) -> 0.030358635 | E97: =E52/SUM($B52:$F52) -> 0.12143144 | F97: =F52/SUM($B52:$F52) -> 0.18033324
A98: 6 | B98: =B53/SUM($B53:$F53) -> 0.29332584 | C98: =C53/SUM($B53:$F53) -> 0.34221446 | D98: =D53/SUM($B53:$F53) -> 0.097775182 | E98: =E53/SUM($B53:$F53) -> 0.048887444 | F98: =F53/SUM($B53:$F53) -> 0.21779708
A99: 7 | B99: =B54/SUM($B54:$F54) -> 0.13049828 | C99: =C54/SUM($B54:$F54) -> 0.41324461 | D99: =D54/SUM($B54:$F54) -> 0.21749758 | E99: =E54/SUM($B54:$F54) -> 0.10874944 | F99: =F54/SUM($B54:$F54) -> 0.13001009
A100: 8 | B100: =B55/SUM($B55:$F55) -> 0 | C100: =C55/SUM($B55:$F55) -> 0.45977011 | D100: =D55/SUM($B55:$F55) -> 0.11494253 | E100: =E55/SUM($B55:$F55) -> 0.22988506 | F100: =F55/SUM($B55:$F55) -> 0.1954023
A101: 9 | B101: =B56/SUM($B56:$F56) -> 0.25647372 | C101: =C56/SUM($B56:$F56) -> 0.10686401 | D101: =D56/SUM($B56:$F56) -> 0.36333734 | E101: =E56/SUM($B56:$F56) -> 0.1496092 | F101: =F56/SUM($B56:$F56) -> 0.12371574
A102: 10 | B102: =B57/SUM($B57:$F57) -> 0.33659145 | C102: =C57/SUM($B57:$F57) -> 0.22439462 | D102: =D57/SUM($B57:$F57) -> 0.15707665 | E102: =E57/SUM($B57:$F57) -> 0.15707611 | F102: =F57/SUM($B57:$F57) -> 0.12486117
A103: 11 | B103: =B58/SUM($B58:$F58) -> 0.126258 | C103: =C58/SUM($B58:$F58) -> 0.33668717 | D103: =D58/SUM($B58:$F58) -> 0.084171918 | E103: =E58/SUM($B58:$F58) -> 0.21043093 | F103: =F58/SUM($B58:$F58) -> 0.24245198
...

Sheet T3_Summary Insight
C3: Attribute | D3: Top-Rated Feature Level | E3: Relative Importance (%) | F3: Average Utility | G3: Baseline Feature Level
C4: Price | D4: Price $450 | E4: ='T2_Relative Importance Anal'!F142 -> 0.2097074 | F4: 0.47 | G4: L1 Price $350
C5: Indoor Features | D5: None (Below baseline) | E5: ='T2_Relative Importance Anal'!F141 -> 0.26916904 | F5: –0.20 to –0.27 | G5: L2 Auto-Brightness Adjustment
C6: Health & Fitness | D6: None (Below baseline) | E6: ='T2_Relative Importance Anal'!F143 -> 0.19254796 | F6: -0.17 | G6: L1 Step & Calorie Tracking / L3 Full Biometric Analysis & AI Coaching
C7: Outdoor Features | D7: Advanced GPS & Live Mapping | E7: ='T2_Relative Importance Anal'!F144 -> 0.17450093 | F7: 0.25 | G7: L1 Basic GPS & Weather Updates
C8: Professional Use | D8: AI Assistant & Hands-Free Control | E8: ='T2_Relative Importance Anal'!F145 -> 0.15407468 | F8: 0.45 | G8: L1 Distraction-Free Alerts

Sheet Report Part2 >>

Sheet T4_Cluster Analysis
A1: Product | B1: 350 | C1: 450 | D1: 550 | E1: Indoor1_Auto-Brightness Adjustment | F1: Indoor2_Smart Adaptive Display | G1: Indoor3_AI-Optimized Vision | H1: Outdoor1_Basic GPS & Weather Updates | I1: Outdoor2_Advanced GPS & Live Mapping | J1: Outdoor3_AR Navigation & Real-Time Environmental Data | K1: Professional1_Distraction-Free Alerts | L1: Professional2_Smart Voice Commands & Reminders | M1: Professional3_AI Assistant & Hands-Free Control | N1: Fitness1_Step & Calorie Tracking | O1: Fitness2_Heart Rate & Workout Insights | P1: Fitness3_Full Biometric Analysis & AI Coaching
A2: Lite | B2: 1 | C2: 0 | D2: 0 | E2: 1 | F2: 0 | G2: 0 | H2: 1 | I2: 0 | J2: 0 | K2: 1 | L2: 0 | M2: 0 | N2: 1 | O2: 0 | P2: 0
A3: Pro | C3: 1 | D3: 0 | E3: 0 | F3: 1 | G3: 0 | H3: 0 | I3: 1 | J3: 0 | K3: 0 | L3: 1 | M3: 0 | N3: 0 | O3: 1 | P3: 0
A4: Elite | B4: 0 | C4: 0 | D4: 1 | E4: 0 | F4: 0 | G4: 1 | H4: 0 | I4: 0 | J4: 1 | K4: 0 | L4: 0 | M4: 1 | N4: 0 | O4: 0 | P4: 1
N7: Count Chosen | O7: =COUNTIF(O9:O49,"<>0") -> 17 | P7: =COUNTIF(P9:P49,"<>0") -> 20 | Q7: =COUNTIF(Q9:Q49,"<>0") -> 20
A8: Respondent | B8: Intercept | C8: 450 | D8: 550 | E8: Indoor2_Smart Adaptive Display | F8: Indoor3_AI-Optimized Vision | G8: Outdoor2_Advanced GPS & Live Mapping | H8: Outdoor3_AR Navigation & Real-Time Environmental Data | I8: Professional2_Smart Voice Commands & Reminders | J8: Professional3_AI Assistant & Hands-Free Control | K8: Fitness2_Heart Rate & Workout Insights | L8: Lite | M8: Pro | N8: Elite | O8: Choose Lite | P8: Choosing Pro | Q8: Choosing Elite | R8: Cluster Names
A9: 1 | B9: 7.1666667 | C9: 2.3333333 | D9: 0.25 | E9: -0.25 | F9: -1.0833333 | G9: -0.66666667 | H9: 0.083333333 | I9: -1.1666667 | J9: -1.3333333 | K9: -1.25 | L9: =B9+($C$2*C9)+(D9*$D$2)+(E9*$F$2)+(F9*$G$2)+(G9*$I$2)+(H9*$J$2)+(I9*$L$2)+(J9*$M$2)+(K9*$O$2) -> 7.1666667 | M9: =B9+($C$3*C9)+(D9*$D$3)+(E9*$F$3)+(F9*$G$3)+(G9*$I$3)+(H9*$J$3)+(I9*$L$3)+(J9*$M$3)+(K9*$O$3) -> 6.1666667 | N9: =B9+($C$4*C9)+(D9*$D$4)+(E9*$F$4)+(F9*$G$4)+(G9*$I$4)+(H9*$J$4)+(I9*$L$4)+(J9*$M$4)+(K9*$O$4) -> 5.0833333 | O9: 1 | P9: 0 | Q9: 0 | R9: Cluster 1
A10: 2 | B10: 5.6666667 | C10: 3.3333333 | D10: 0.58333333 | E10: -0.41666667 | F10: -3.25 | G10: -2.6666667 | H10: -2.75 | I10: 0.83333333 | J10: 0.66666667 | K10: -2.0833333 | L10: =B10+($C$2*C10)+(D10*$D$2)+(E10*$F$2)+(F10*$G$2)+(G10*$I$2)+(H10*$J$2)+(I10*$L$2)+(J10*$M$2)+(K10*$O$2) -> 5.6666667 | M10: =B10+($C$3*C10)+(D10*$D$3)+(E10*$F$3)+(F10*$G$3)+(G10*$I$3)+(H10*$J$3)+(I10*$L$3)+(J10*$M$3)+(K10*$O$3) -> 4.6666667 | N10: =B10+($C$4*C10)+(D10*$D$4)+(E10*$F$4)+(F10*$G$4)+(G10*$I$4)+(H10*$J$4)+(I10*$L$4)+(J10*$M$4)+(K10*$O$4) -> 0.91666667 | O10: 1 | P10: 0 | Q10: 0 | R10: Cluster 2
A11: 3 | B11: 5.8333333 | C11: 3.6666667 | D11: 2.5 | E11: 8.4525467e-16 | F11: -3.6666667 | G11: -2.3333333 | H11: -1.3333333 | I11: -0.33333333 | J11: 0.33333333 | K11: -1 | L11: =B11+($C$2*C11)+(D11*$D$2)+(E11*$F$2)+(F11*$G$2)+(G11*$I$2)+(H11*$J$2)+(I11*$L$2)+(J11*$M$2)+(K11*$O$2) -> 5.8333333 | M11: =B11+($C$3*C11)+(D11*$D$3)+(E11*$F$3)+(F11*$G$3)+(G11*$I$3)+(H11*$J$3)+(I11*$L$3)+(J11*$M$3)+(K11*$O$3) -> 5.8333333 | N11: =B11+($C$4*C11)+(D11*$D$4)+(E11*$F$4)+(F11*$G$4)+(G11*$I$4)+(H11*$J$4)+(I11*$L$4)+(J11*$M$4)+(K11*$O$4) -> 3.6666667 | O11: 0.5 | P11: 0.5 | Q11: 0 | R11: Cluster 2
A12: 4 | B12: 1.1666667 | C12: -1.6666667 | D12: -0.25 | E12: 0.25 | F12: 1.4166667 | G12: 2.3333333 | H12: 1.5833333 | I12: 0.83333333 | J12: 0.66666667 | K12: 0.25 | L12: =B12+($C$2*C12)+(D12*$D$2)+(E12*$F$2)+(F12*$G$2)+(G12*$I$2)+(H12*$J$2)+(I12*$L$2)+(J12*$M$2)+(K12*$O$2) -> 1.1666667 | M12: =B12+($C$3*C12)+(D12*$D$3)+(E12*$F$3)+(F12*$G$3)+(G12*$I$3)+(H12*$J$3)+(I12*$L$3)+(J12*$M$3)+(K12*$O$3) -> 3.1666667 | N12: =B12+($C$4*C12)+(D12*$D$4)+(E12*$F$4)+(F12*$G$4)+(G12*$I$4)+(H12*$J$4)+(I12*$L$4)+(J12*$M$4)+(K12*$O$4) -> 4.5833333 | O12: 0 | P12: 0 | Q12: 1 | R12: Cluster 1
A13: 5 | B13: 4.1666667 | C13: -0.66666667 | D13: -2.0833333 | E13: 0.41666667 | F13: 3.5833333 | G13: -0.66666667 | H13: 1.4166667 | I13: -1.1666667 | J13: -0.33333333 | K13: 0.083333333 | L13: =B13+($C$2*C13)+(D13*$D$2)+(E13*$F$2)+(F13*$G$2)+(G13*$I$2)+(H13*$J$2)+(I13*$L$2)+(J13*$M$2)+(K13*$O$2) -> 4.1666667 | M13: =B13+($C$3*C13)+(D13*$D$3)+(E13*$F$3)+(F13*$G$3)+(G13*$I$3)+(H13*$J$3)+(I13*$L$3)+(J13*$M$3)+(K13*$O$3) -> 2.1666667 | N13: =B13+($C$4*C13)+(D13*$D$4)+(E13*$F$4)+(F13*$G$4)+(G13*$I$4)+(H13*$J$4)+(I13*$L$4)+(J13*$M$4)+(K13*$O$4) -> 6.75 | O13: 0 | P13: 0 | Q13: 1 | R13: Cluster 1
A14: 6 | B14: 5.5 | C14: 2 | D14: 1.8333333 | E14: -0.66666667 | F14: -2.6666667 | G14: -1 | H14: -0.33333333 | I14: 6.5794839e-16 | J14: 1 | K14: -1.3333333 | L14: =B14+($C$2*C14)+(D14*$D$2)+(E14*$F$2)+(F14*$G$2)+(G14*$I$2)+(H14*$J$2)+(I14*$L$2)+(J14*$M$2)+(K14*$O$2) -> 5.5 | M14: =B14+($C$3*C14)+(D14*$D$3)+(E14*$F$3)+(F14*$G$3)+(G14*$I$3)+(H14*$J$3)+(I14*$L$3)+(J14*$M$3)+(K14*$O$3) -> 4.5 | N14: =B14+($C$4*C14)+(D14*$D$4)+(E14*$F$4)+(F14*$G$4)+(G14*$I$4)+(H14*$J$4)+(I14*$L$4)+(J14*$M$4)+(K14*$O$4) -> 5.3333333 | O14: 0.5 | P14: 0 | Q14: 0.5 | R14: Cluster 2
A15: 7 | B15: 4.6666667 | C15: 0.33333333 | D15: 0.25 | E15: 0.25 | F15: -0.58333333 | G15: -0.66666667 | H15: -1.4166667 | I15: 0.83333333 | J15: -0.33333333 | K15: -0.75 | L15: =B15+($C$2*C15)+(D15*$D$2)+(E15*$F$2)+(F15*$G$2)+(G15*$I$2)+(H15*$J$2)+(I15*$L$2)+(J15*$M$2)+(K15*$O$2) -> 4.6666667 | M15: =B15+($C$3*C15)+(D15*$D$3)+(E15*$F$3)+(F15*$G$3)+(G15*$I$3)+(H15*$J$3)+(I15*$L$3)+(J15*$M$3)+(K15*$O$3) -> 4.6666667 | N15: =B15+($C$4*C15)+(D15*$D$4)+(E15*$F$4)+(F15*$G$4)+(G15*$I$4)+(H15*$J$4)+(I15*$L$4)+(J15*$M$4)+(K15*$O$4) -> 2.5833333 | O15: 0.33 | P15: 0.33 | Q15: 0.33 | R15: Cluster 2
A16: 8 | B16: 2.3333333 | C16: -1.3333333 | D16: -0.5 | E16: 2 | F16: 0.33333333 | G16: -2.8333333 | H16: -2.3333333 | I16: 1.6666667 | J16: 2.8333333 | K16: 2.5 | L16: =B16+($C$2*C16)+(D16*$D$2)+(E16*$F$2)+(F16*$G$2)+(G16*$I$2)+(H16*$J$2)+(I16*$L$2)+(J16*$M$2)+(K16*$O$2) -> 2.3333333 | M16: =B16+($C$3*C16)+(D16*$D$3)+(E16*$F$3)+(F16*$G$3)+(G16*$I$3)+(H16*$J$3)+(I16*$L$3)+(J16*$M$3)+(K16*$O$3) -> 4.3333333 | N16: =B16+($C$4*C16)+(D16*$D$4)+(E16*$F$4)+(F16*$G$4)+(G16*$I$4)+(H16*$J$4)+(I16*$L$4)+(J16*$M$4)+(K16*$O$4) -> 2.6666667 | O16: 0 | P16: 0.5 | Q16: 0.5 | R16: Cluster 2
A17: 9 | B17: 5.8333333 | C17: -0.33333333 | D17: -0.33333333 | E17: -0.33333333 | F17: 1 | G17: 1.1666667 | H17: 1 | I17: 0.66666667 | J17: -0.16666667 | K17: -0.16666667 | L17: =B17+($C$2*C17)+(D17*$D$2)+(E17*$F$2)+(F17*$G$2)+(G17*$I$2)+(H17*$J$2)+(I17*$L$2)+(J17*$M$2)+(K17*$O$2) -> 5.8333333 | M17: =B17+($C$3*C17)+(D17*$D$3)+(E17*$F$3)+(F17*$G$3)+(G17*$I$3)+(H17*$J$3)+(I17*$L$3)+(J17*$M$3)+(K17*$O$3) -> 6.8333333 | N17: =B17+($C$4*C17)+(D17*$D$4)+(E17*$F$4)+(F17*$G$4)+(G17*$I$4)+(H17*$J$4)+(I17*$L$4)+(J17*$M$4)+(K17*$O$4) -> 7.3333333 | O17: 0 | P17: 0.5 | Q17: 0.5 | R17: Cluster 1
A18: 10 | B18: 1.1666667 | C18: 3.3333333 | D18: 2.1666667 | E18: 1.6666667 | F18: -0.66666667 | G18: -2.6666667 | H18: -1.3333333 | I18: 2.3333333 | J18: 0.66666667 | K18: 1.3333333 | L18: =B18+($C$2*C18)+(D18*$D$2)+(E18*$F$2)+(F18*$G$2)+(G18*$I$2)+(H18*$J$2)+(I18*$L$2)+(J18*$M$2)+(K18*$O$2) -> 1.1666667 | M18: =B18+($C$3*C18)+(D18*$D$3)+(E18*$F$3)+(F18*$G$3)+(G18*$I$3)+(H18*$J$3)+(I18*$L$3)+(J18*$M$3)+(K18*$O$3) -> 7.1666667 | N18: =B18+($C$4*C18)+(D18*$D$4)+(E18*$F$4)+(F18*$G$4)+(G18*$I$4)+(H18*$J$4)+(I18*$L$4)+(J18*$M$4)+(K18*$O$4) -> 2 | O18: 0 | P18: 1 | Q18: 0 | R18: Cluster 2
A19: 11 | B19: 6.6666667 | C19: -0.66666667 | D19: -2.25 | E19: -0.75 | F19: 2.4166667 | G19: -0.16666667 | H19: 2.5833333 | I19: -1.1666667 | J19: -2.8333333 | K19: -2.25 | L19: =B19+($C$2*C19)+(D19*$D$2)+(E19*$F$2)+(F19*$G$2)+(G19*$I$2)+(H19*$J$2)+(I19*$L$2)+(J19*$M$2)+(K19*$O$2) -> 6.6666667 | M19: =B19+($C$3*C19)+(D19*$D$3)+(E19*$F$3)+(F19*$G$3)+(G19*$I$3)+(H19*$J$3)+(I19*$L$3)+(J19*$M$3)+(K19*$O$3) -> 1.6666667 | N19: =B19+($C$4*C19)+(D19*$D$4)+(E19*$F$4)+(F19*$G$4)+(G19*$I$4)+(H19*$J$4)+(I19*$L$4)+(J19*$M$4)+(K19*$O$4) -> 6.5833333 | O19: 1 | P19: 0 | Q19: 0 | R19: Cluster 1
A20: 12 | B20: 5.3333333 | C20: -0.33333333 | D20: 0.33333333 | E20: 0.33333333 | F20: -2.3333333 | G20: -0.33333333 | H20: -0.66666667 | I20: 0.66666667 | J20: 1.3333333 | K20: -0.33333333 | L20: =B20+($C$2*C20)+(D20*$D$2)+(E20*$F$2)+(F20*$G$2)+(G20*$I$2)+(H20*$J$2)+(I20*$L$2)+(J20*$M$2)+(K20*$O$2) -> 5.3333333 | M20: =B20+($C$3*C20)+(D20*$D$3)+(E20*$F$3)+(F20*$G$3)+(G20*$I$3)+(H20*$J$3)+(I20*$L$3)+(J20*$M$3)+(K20*$O$3) -> 5.3333333 | N20: =B20+($C$4*C20)+(D20*$D$4)+(E20*$F$4)+(F20*$G$4)+(G20*$I$4)+(H20*$J$4)+(I20*$L$4)+(J20*$M$4)+(K20*$O$4) -> 4 | O20: 0.5 | P20: 0.5 | Q20: 0 | R20: Cluster 2
... A49: 41 | B49: 4.8333333 | C49: -0.33333333 | D49: 0.083333333 | E49: -0.91666667 | F49: -0.083333333 | G49: 2.1666667 | H49: 2.0833333 | I49: -0.83333333 | J49: -0.16666667 | K49: -1.0833333 | L49: =B49+($C$2*C49)+(D49*$D$2)+(E49*$F$2)+(F49*$G$2)+(G49*$I$2)+(H49*$J$2)+(I49*$L$2)+(J49*$M$2)+(K49*$O$2) -> 4.8333333 | M49: =B49+($C$3*C49)+(D49*$D$3)+(E49*$F$3)+(F49*$G$3)+(G49*$I$3)+(H49*$J$3)+(I49*$L$3)+(J49*$M$3)+(K49*$O$3) -> 3.8333333 | N49: =B49+($C$4*C49)+(D49*$D$4)+(E49*$F$4)+(F49*$G$4)+(G49*$I$4)+(H49*$J$4)+(I49*$L$4)+(J49*$M$4)+(K49*$O$4) -> 6.75 | O49: 0.5 | P49: 0 | Q49: 0.5 | R49: Cluster 1
K50: Average Utility = | L50: =AVERAGE(L9:L49) -> 4.3577236 | M50: =AVERAGE(M9:M49) -> 4.9674797 | N50: =AVERAGE(N9:N49) -> 4.7581301 | O50: =SUM(O9:O49) -> 11.16 | P50: =SUM(P9:P49) -> 15.66 | Q50: =SUM(Q9:Q49) -> 14.16
K51: Rank = | L51: 3 | M51: 1 | N51: 2
O53: Rank By Demand
O54: Products | P54: Count | Q54: Market Interest | R54: Rank
O55: Lite | P55: 11.16 | Q55: =P55/$P$58 -> 0.27232796 | R55: 3
O56: Pro | P56: 15.66 | Q56: =P56/$P$58 -> 0.38213763 | R56: 1
O57: Elite | P57: 14.16 | Q57: =P57/$P$58 -> 0.34553441 | R57: 2
O58: Total= | P58: =SUM(P55:P57) -> 40.98
O60: Choice per Cluster
J61: Row Labels | K61: Average of Choose Lite | L61: Average of Choosing Pro | M61: Average of Choosing Elite | O61: Row Labels | P61: Average of Choose Lite | Q61: Average of Choosing Pro | R61: Average of Choosing Elite
J62: Cluster 1 | K62: 0.422 | L62: 0.122 | M62: 0.45533333 | O62: Cluster 1 | P62: 0.422 | Q62: 0.122 | R62: 0.45533333
J63: Cluster 2 | K63: 0.17409091 | L63: 0.53772727 | M63: 0.28772727 | O63: Cluster 2 | P63: 0.17409091 | Q63: 0.53772727 | R63: 0.28772727
J64: Cluster 3 | K64: 0.25 | L64: 0.5 | M64: 0.25 | O64: Cluster 3 | P64: 0.25 | Q64: 0.5 | R64: 0.25
J65: Grand Total | K65: 0.27219512 | L65: 0.38195122 | M65: 0.34536585

Sheet T4.2_Summary Cluster
A1: Option | B1: Intercept | C1: 450 | D1: 550 | E1: Indoor2_Smart Adaptive Display | F1: Indoor3_AI-Optimized Vision | G1: Outdoor2_Advanced GPS & Live Mapping | H1: Outdoor3_AR Navigation & Real-Time Environmental Data | I1: Professional2_Smart Voice Commands & Reminders | J1: Professional3_AI Assistant & Hands-Free Control | K1: Fitness2_Heart Rate & Workout Insights | L1: R_squared | M1: Age | N1: Cluster Names | O1: Education Level | P1: Gender | Q1: Occupation | R1: Pincode | S1: State | T1: Income | U1: Option
A2: 1 | B2: 7.1666667 | C2: 2.3333333 | D2: 0.33333333 | E2: -0.16666667 | F2: -1 | G2: -0.66666667 | H2: -9.7414327e-16 | I2: -1.1666667 | J2: -1.3333333 | K2: -1.3333333 | L2: 0.97587719 | M2: 18-24 | N2: Cluster 1 | O2: Graduate or professional degree (MA, MS, MBA, PhD, Law Degree, Medical Degree etc) | P2: Male | Q2: Student | R2: 2009 | S2: New South Wales | T2: 1000 | U2: 1
A3: 2 | B3: 5.6666667 | C3: 3.3333333 | D3: 2.3333333 | E3: 1.3333333 | F3: -1.5 | G3: -2.6666667 | H3: -4.5 | I3: 0.83333333 | J3: 0.66666667 | K3: -3.8333333 | L3: 0.97505669 | M3: 25-34 | N3: Cluster 2 | O3: Graduate or professional degree (MA, MS, MBA, PhD, Law Degree, Medical Degree etc) | P3: Female | Q3: Student | R3: 3020 | S3: Victoria | T3: 3000 | U3: 2
A4: 3 | B4: 5.8333333 | C4: 3.6666667 | D4: 3.6666667 | E4: 1.1666667 | F4: -2.5 | G4: -2.3333333 | H4: -2.5 | I4: -0.33333333 | J4: 0.33333333 | K4: -2.1666667 | L4: 0.99003623 | M4: 25-34 | N4: Cluster 2 | O4: University - Bachelors Degree | P4: Female | Q4: Student | R4: 2140 | S4: New South Wales | T4: 1000 | U4: 5
A5: 4 | B5: 1.1666667 | C5: -1.6666667 | D5: -0.66666667 | E5: -0.16666667 | F5: 1 | G5: 2.3333333 | H5: 2 | I5: 0.83333333 | J5: 0.66666667 | K5: 0.66666667 | L5: 0.74250936 | M5: 25-34 | N5: Cluster 3 | O5: University - Bachelors Degree | P5: Female | Q5: Employee | R5: 2140 | S5: New South Wales | T5: 3000 | U5: 6
A6: 5 | B6: 4.1666667 | C6: -0.66666667 | D6: -1.6666667 | E6: 0.83333333 | F6: 4 | G6: -0.66666667 | H6: 1 | I6: -1.1666667 | J6: -0.33333333 | K6: -0.33333333 | L6: 0.9962585 | M6: 25-34 | N6: Cluster 1 | O6: Vocational or Similar | P6: Male | Q6: Employee | R6: 2140 | S6: New South Wales | T6: 3000 | U6: 7
A7: 6 | B7: 5.5 | C7: 2 | D7: 2 | E7: -0.5 | F7: -2.5 | G7: -1 | H7: -0.5 | I7: 2.5330249e-16 | J7: 1 | K7: -1.5 | L7: 0.85 | M7: 18-24 | N7: Cluster 2 | O7: Graduate or professional degree (MA, MS, MBA, PhD, Law Degree, Medical Degree etc) | P7: Prefer not to say | Q7: Student | S7: New South Wales | T7: 999 | U7: 8
A8: 7 | B8: 4.6666667 | C8: 0.33333333 | D8: 2.3333333 | E8: 2.3333333 | F8: 1.5 | G8: -0.66666667 | H8: -3.5 | I8: 0.83333333 | J8: -0.33333333 | K8: -2.8333333 | L8: 0.96474359 | M8: 25-34 | N8: Cluster 2 | O8: University - Bachelors Degree | P8: Male | Q8: Student | R8: 2131 | S8: New South Wales | T8: 1000 | U8: 9
A9: 8 | B9: 2.3333333 | C9: -1.3333333 | D9: 1.1666667 | E9: 3.6666667 | F9: 2 | G9: -2.8333333 | H9: -4 | I9: 1.6666667 | J9: 2.8333333 | K9: 0.83333333 | L9: 0.92739274 | M9: 45+ | N9: Cluster 2 | O9: Graduate or professional degree (MA, MS, MBA, PhD, Law Degree, Medical Degree etc) | P9: Female | Q9: Student | R9: 2010 | S9: New South Wales | T9: 5001 | U9: 10
A10: 9 | B10: 5.8333333 | C10: -0.33333333 | D10: -0.83333333 | E10: -0.83333333 | F10: 0.5 | G10: 1.1666667 | H10: 1.5 | I10: 0.66666667 | J10: -0.16666667 | K10: 0.33333333 | L10: 0.96014493 | M10: 18-24 | N10: Cluster 1 | O10: University - Bachelors Degree | P10: Female | Q10: Student | R10: 2017 | S10: New South Wales | T10: 5001 | U10: 11
A11: 10 | B11: 1.1666667 | C11: 3.3333333 | D11: 5.3333333 | E11: 4.8333333 | F11: 2.5 | G11: -2.6666667 | H11: -4.5 | I11: 2.3333333 | J11: 0.66666667 | K11: -1.8333333 | L11: 0.99444444 | M11: 18-24 | N11: Cluster 2 | O11: University - Bachelors Degree | P11: Female | Q11: Student | R11: 2077 | S11: New South Wales | T11: 999 | U11: 13
A12: 11 | B12: 6.6666667 | C12: -0.66666667 | D12: -3.1666667 | E12: -1.6666667 | F12: 1.5 | G12: -0.16666667 | H12: 3.5 | I12: -1.1666667 | J12: -2.8333333 | K12: -1.3333333 | L12: 0.98671498 | M12: 18-24 | N12: Cluster 1 | O12: Graduate or professional degree (MA, MS, MBA, PhD, Law Degree, Medical Degree etc) | P12: Female | Q12: Student | R12: 2179 | S12: New South Wales | T12: 3000 | U12: 14
A13: 12 | B13: 5.3333333 | C13: -0.33333333 | D13: -0.33333333 | E13: -0.33333333 | F13: -3 | G13: -0.33333333 | H13: 1.2513301e-15 | I13: 0.66666667 | J13: 1.3333333 | K13: 0.33333333 | L13: 0.94270833 | M13: 25-34 | N13: Cluster 2 | O13: University - Bachelors Degree | P13: Male | Q13: Student | R13: 2150 | S13: New South Wales | T13: 1000 | U13: 16
A14: 13 | B14: 5.3333333 | C14: -2.3333333 | D14: -0.33333333 | E14: -0.33333333 | F14: 0.5 | G14: -0.33333333 | H14: 0.5 | I14: 0.16666667 | J14: 0.33333333 | K14: 1.8333333 | L14: 0.92198582 | M14: 25-34 | N14: Cluster 1 | O14: Graduate or professional degree (MA, MS, MBA, PhD, Law Degree, Medical Degree etc) | P14: Female | Q14: Student | R14: 2148 | S14: New South Wales | T14: 1000 | U14: 17
A15: 14 | B15: 4.1666667 | C15: -4.6666667 | D15: -4.1666667 | E15: -1.1666667 | F15: 2.5 | G15: 2.8333333 | H15: 2.5 | I15: -1.6666667 | J15: -0.83333333 | K15: 3.6666667 | L15: 0.98472222 | M15: 25-34 | N15: Cluster 3 | O15: University - Bachelors Degree | P15: Female | Q15: Student | R15: 2150 | S15: New South Wales | T15: 999 | U15: 18
A16: 15 | B16: 5.3333333 | C16: -0.33333333 | D16: 0.16666667 | E16: -0.33333333 | F16: -0.5 | G16: 1.1666667 | H16: 0.5 | I16: -0.83333333 | J16: -0.16666667 | K16: -0.66666667 | L16: 0.75555556 | M16: 25-34 | N16: Cluster 1 | O16: University - Bachelors Degree | P16: Male | Q16: Student | R16: 2150 | S16: New South Wales | T16: 1000 | U16: 20
A17: 16 | B17: 3.6666667 | C17: 2.3333333 | D17: 1.8333333 | E17: 1.3333333 | F17: -0.5 | G17: -0.16666667 | H17: -1.5 | I17: -0.16666667 | J17: -0.83333333 | K17: -2.3333333 | L17: 0.93678161 | M17: 25-34 | N17: Cluster 2 | O17: University - Bachelors Degree | P17: Male | Q17: Student | R17: 2007 | S17: New South Wales | T17: 999 | U17: 22
A18: 17 | B18: 6.1666667 | C18: 1.3333333 | D18: -0.16666667 | E18: -1.1666667 | F18: -0.5 | G18: 0.83333333 | H18: 0.5 | I18: -0.66666667 | J18: -1.8333333 | K18: 0.66666667 | L18: 0.98446328 | M18: 25-34 | N18: Cluster 1 | O18: Graduate or professional degree (MA, MS, MBA, PhD, Law Degree, Medical Degree etc) | P18: Male | Q18: Student | R18: 2142 | S18: New South Wales | T18: 5001 | U18: 23
A19: 18 | B19: 2.3333333 | C19: -0.33333333 | D19: -0.83333333 | E19: -1.3333333 | F19: -1.5 | G19: 2.1666667 | H19: 1.5 | I19: 1.1666667 | J19: 1.8333333 | K19: 3.3333333 | L19: 0.9819376 | M19: 25-34 | N19: Cluster 3 | O19: University - Bachelors Degree | P19: Male | Q19: Student | R19: 2016 | S19: New South Wales | T19: 1000 | U19: 24
... A29: 28 | B29: 5 | C29: 2 | D29: 2 | E29: 2 | F29: -1.5 | G29: -2 | H29: -3.5 | I29: 0.5 | J29: -2.4752493e-15 | K29: -0.5 | L29: 1 | M29: 25-34 | N29: Cluster 2 | O29: Graduate or professional degree (MA, MS, MBA, PhD, Law Degree, Medical Degree etc) | P29: Male | Q29: Student | R29: 2016 | S29: New South Wales | T29: 3000 | U29: 35
A30: 29 | B30: 3 | C30: -1.0819872e-15 | D30: 0.5 | E30: 1 | F30: 1.5 | G30: 0.5 | H30: 0.5 | I30: -0.5 | J30: 0.5 | K30: 1.0550461e-15 | L30: 1 | M30: 18-24 | N30: Cluster 1 | O30: Graduate or professional degree (MA, MS, MBA, PhD, Law Degree, Medical Degree etc) | P30: Female | Q30: Student | S30: New South Wales | T30: 999 | U30: 36
A31: 30 | B31: 5.6666667 | C31: -0.66666667 | D31: -0.16666667 | E31: -0.66666667 | F31: -0.5 | G31: 0.83333333 | H31: -0.5 | I31: -0.16666667 | J31: -1.8333333 | K31: -1.3333333 | L31: 0.96811594 | M31: 25-34 | N31: Cluster 1 | O31: University - Bachelors Degree | P31: Female | Q31: Student | R31: 2031 | S31: New South Wales | T31: 1000 | U31: 37
A32: 31 | B32: 7.5 | C32: -1 | D32: -1 | E32: -1.5 | F32: -1 | G32: -8.4929795e-16 | H32: 6.6460411e-17 | I32: -1.5 | J32: -1 | K32: -2 | L32: 0.95680628 | M32: 18-24 | N32: Cluster 1 | O32: University - Bachelors Degree | P32: Female | Q32: Student | R32: 2154 | S32: South Australia | T32: 999 | U32: 39
A33: 32 | B33: 4 | C33: 5 | D33: 2.4424907e-15 | E33: -1 | F33: -3 | G33: -2.2989597e-15 | H33: 1 | I33: 1 | J33: 3 | K33: -2 | L33: 1 | M33: 25-34 | N33: Cluster 2 | O33: University - Bachelors Degree | P33: Male | Q33: Student | R33: 2000 | S33: New South Wales | T33: 3000 | U33: 40
A34: 33 | B34: 3 | C34: 1 | D34: 0.5 | E34: -1 | F34: -0.5 | G34: 0.5 | H34: -0.5 | I34: 1.5 | J34: 3.5 | K34: 4.2723131e-16 | L34: 1 | M34: 18-24 | N34: Cluster 2 | O34: University - Bachelors Degree | P34: Female | Q34: Student | R34: 2000 | S34: New South Wales | T34: 3000 | U34: 41
A35: 34 | B35: 3.1666667 | C35: 3.3333333 | D35: -0.16666667 | E35: -2.1666667 | F35: -2 | G35: 0.83333333 | H35: 2 | I35: 0.83333333 | J35: 3.1666667 | K35: -0.83333333 | L35: 0.99504505 | M35: 25-34 | N35: Cluster 2 | O35: University - Bachelors Degree | P35: Male | Q35: Student | R35: 2010 | S35: New South Wales | T35: 3000 | U35: 42
A36: 35 | B36: 2.3333333 | C36: 1.6666667 | D36: -0.83333333 | E36: -0.33333333 | F36: -2 | G36: -0.83333333 | H36: 2.5730348e-16 | I36: 2.6666667 | J36: 4.8333333 | K36: -0.16666667 | L36: 0.98355755 | M36: 25-34 | N36: Cluster 2 | O36: University - Bachelors Degree | P36: Female | Q36: Student | R36: 2060 | S36: New South Wales | T36: 1000 | U36: 43
A37: 36 | B37: 4 | C37: 3 | D37: 1 | E37: -1.130271e-15 | F37: -3.5 | G37: 1 | H37: -0.5 | I37: 1.5 | J37: 2 | K37: -3.5 | L37: 1 | M37: 25-34 | N37: Cluster 2 | O37: University - Bachelors Degree | P37: Female | Q37: Student | R37: 2057 | S37: New South Wales | T37: 1000 | U37: 44
A38: 37 | B38: 4.8333333 | C38: -2.3333333 | D38: -0.83333333 | E38: -3.8333333 | F38: -1 | G38: 2.1666667 | H38: 2 | I38: 0.16666667 | J38: -1.1666667 | K38: 2.8333333 | L38: 0.99444444 | M38: 25-34 | N38: Cluster 3 | O38: University - Bachelors Degree | P38: Male | Q38: Student | R38: 2160 | S38: New South Wales | T38: 999 | U38: 45
A39: 38 | B39: 4.3333333 | C39: -5.3333333 | D39: -2.8333333 | E39: -2.3333333 | F39: 2 | G39: 4.1666667 | H39: 1 | I39: -1.3333333 | J39: -2.1666667 | K39: 4.8333333 | L39: 0.96474359 | M39: 18-24 | N39: Cluster 3 | O39: University - Bachelors Degree | P39: Male | Q39: Student | R39: 2017 | S39: New South Wales | T39: 999 | U39: 48
A40: 39 | B40: 2.6666667 | C40: -4.6666667 | D40: 0.83333333 | E40: 2.3333333 | F40: 5.5 | G40: 1.8333333 | H40: -2.5 | I40: -1.1666667 | J40: -1.8333333 | K40: 3.6666667 | L40: 0.9769392 | M40: 18-24 | N40: Cluster 3 | O40: University - Bachelors Degree | P40: Male | Q40: Student | R40: 2017 | S40: New South Wales | T40: 999 | U40: 52
A41: 40 | B41: 4.1666667 | C41: 1.3333333 | D41: -0.16666667 | E41: -2.1666667 | F41: 1.5 | G41: 2.8333333 | H41: 0.5 | I41: -1.6666667 | J41: 0.16666667 | K41: -1.3333333 | L41: 0.99656679 | M41: 25-34 | N41: Cluster 1 | O41: University - Bachelors Degree | P41: Female | Q41: Student | R41: 2057 | S41: New South Wales | T41: 1000 | U41: 61
A42: 41 | B42: 4.8333333 | C42: -0.33333333 | D42: -1.8333333 | E42: -2.8333333 | F42: -2 | G42: 2.1666667 | H42: 4 | I42: -0.83333333 | J42: -0.16666667 | K42: 0.83333333 | L42: 0.98882114 | M42: 25-34 | N42: Cluster 1 | O42: University - Bachelors Degree | P42: Female | Q42: Student | R42: 2010 | S42: New South Wales | U42: 67

Sheet T4.3_Cluster Demographic
B1: Cluster Analysis without Demographic data
B13: Clustering Analysis with demographic data
