Workbook

Sheet Budget
B1: Restaurant Monthly Cash Budget
C3: Month | D3: July | E3: August | F3: September | G3: October | H3: November | I3: December | J3: January | K3: February | L3: March | M3: April | N3: May | O3: June | P3: Year
C4: Period start date | D4: 43647 | E4: 43678 | F4: 43709 | G4: 43739 | H4: 43770 | I4: 43800 | J4: 43831 | K4: 43862 | L4: 43891 | M4: 43922 | N4: 43952 | O4: 43983 | P4: =D4 -> 43647
C5: Period end date | D5: 43677 | E5: 43708 | F5: 43738 | G5: 43769 | H5: 43799 | I5: 43830 | J5: 43861 | K5: 43890 | L5: 43921 | M5: 43951 | N5: 43982 | O5: 44012 | P5: =O5 -> 44012
C6: Days in month | D6: =_xlfn.DAYS(D5,D4)+1 -> 31 | E6: =_xlfn.DAYS(E5,E4)+1 -> 31 | F6: =_xlfn.DAYS(F5,F4)+1 -> 30 | G6: =_xlfn.DAYS(G5,G4)+1 -> 31 | H6: =_xlfn.DAYS(H5,H4)+1 -> 30 | I6: =_xlfn.DAYS(I5,I4)+1 -> 31 | J6: =_xlfn.DAYS(J5,J4)+1 -> 31 | K6: =_xlfn.DAYS(K5,K4)+1 -> 29 | ... P6: =_xlfn.DAYS(P5,P4)+1 -> 366
B9: Revenue
B10: Forecast restaurant capacity utilization | D10: 0.6 | E10: 0.75 | F10: 0.77 | G10: =80% -> 0.8 | H10: 0.85 | I10: 0.65 | J10: 0.8 | K10: 0.9 | L10: 0.87 | M10: 0.83 | N10: 0.82 | O10: 0.78 | P10: =AVERAGE(D10:O10) -> 0.785
B11: Customers | D11: =D6*$C$34*D10*$C$35 -> 2790 | E11: =E6*$C$34*E10*$C$35 -> 3487.5 | F11: =F6*$C$34*F10*$C$35 -> 3465 | G11: =G6*$C$34*G10*$C$35 -> 3720 | H11: =H6*$C$34*H10*$C$35 -> 3825 | I11: =I6*$C$34*I10*$C$35 -> 3022.5 | J11: =J6*$C$34*J10*$C$35 -> 3720 | K11: =K6*$C$34*K10*$C$35 -> 3915 | ... O11: =O6*$C$34*O10*$C$35 -> 3510 | P11: =SUM(D11:O11) -> 43048.5
B12: Food | D12: =D11*$C$37 -> 83700 | E12: =E11*$C$37 -> 104625 | F12: =F11*$C$37 -> 103950 | G12: =G11*$C$37 -> 111600 | H12: =H11*$C$37 -> 114750 | I12: =I11*$C$37 -> 90675 | J12: =J11*$C$37 -> 111600 | K12: =K11*$C$37 -> 117450 | ... O12: =O11*$C$37 -> 105300 | P12: =SUM(D12:O12) -> 1291455
B13: Beverages | D13: =D11*$C$38 -> 41850 | E13: =E11*$C$38 -> 52312.5 | F13: =F11*$C$38 -> 51975 | G13: =G11*$C$38 -> 55800 | H13: =H11*$C$38 -> 57375 | I13: =I11*$C$38 -> 45337.5 | J13: =J11*$C$38 -> 55800 | K13: =K11*$C$38 -> 58725 | ... O13: =O11*$C$38 -> 52650 | P13: =SUM(D13:O13) -> 645727.5
B14: Total Revenue | D14: =SUM(D12:D13) -> 125550 | E14: =SUM(E12:E13) -> 156937.5 | F14: =SUM(F12:F13) -> 155925 | G14: =SUM(G12:G13) -> 167400 | H14: =SUM(H12:H13) -> 172125 | I14: =SUM(I12:I13) -> 136012.5 | J14: =SUM(J12:J13) -> 167400 | K14: =SUM(K12:K13) -> 176175 | ... P14: =SUM(P12:P13) -> 1937182.5
B16: Expenses
B17: Food Supplies | D17: =D12*$C$39 -> 25110 | E17: =E12*$C$39 -> 31387.5 | F17: =F12*$C$39 -> 31185 | G17: =G12*$C$39 -> 33480 | H17: =H12*$C$39 -> 34425 | I17: =I12*$C$39 -> 27202.5 | J17: =J12*$C$39 -> 33480 | K17: =K12*$C$39 -> 35235 | ... O17: =O12*$C$39 -> 31590 | P17: =SUM(D17:O17) -> 387436.5
B18: Beverage Supplies | D18: =D13*$C$40 -> 14647.5 | E18: =E13*$C$40 -> 18309.375 | F18: =F13*$C$40 -> 18191.25 | G18: =G13*$C$40 -> 19530 | H18: =H13*$C$40 -> 20081.25 | I18: =I13*$C$40 -> 15868.125 | J18: =J13*$C$40 -> 19530 | K18: =K13*$C$40 -> 20553.75 | ... O18: =O13*$C$40 -> 18427.5 | P18: =SUM(D18:O18) -> 226004.62
B19: Rent | D19: =$C$41/12 -> 16666.667 | E19: =$C$41/12 -> 16666.667 | F19: =$C$41/12 -> 16666.667 | G19: =$C$41/12 -> 16666.667 | H19: =$C$41/12 -> 16666.667 | I19: =$C$41/12 -> 16666.667 | J19: =$C$41/12 -> 16666.667 | K19: =$C$41/12 -> 16666.667 | ... O19: =$C$41/12 -> 16666.667 | P19: =SUM(D19:O19) -> 200000
B20: Wages* | D20: =SUM(F49:G52) -> 74900 | E20: =SUM(F49:G52) -> 74900 | F20: =SUM(F49:G52) -> 74900 | G20: =SUM(F49:G52) -> 74900 | H20: =SUM(F49:G52) -> 74900 | I20: =SUM(F49:G52) -> 74900 | J20: =SUM(F49:G52) -> 74900 | K20: =SUM(F49:G52) -> 74900 | L20: =SUM(F49:G52) -> 74900 | M20: =SUM(F49:G52) -> 74900 | N20: =SUM(F49:G52) -> 74900 | O20: =SUM(F49:G52) -> 74900 | P20: =SUM(D20:O20) -> 898800
B21: Utilities | D21: 1517.1099 | E21: 1641.903 | F21: 1568.5382 | G21: 1605.3332 | H21: 1666.1579 | I21: 1419.1735 | J21: 1614.5533 | K21: 1692.0491 | L21: 1730.4308 | M21: 1646.0446 | N21: 1697.1746 | O21: 1613.4047 | P21: =SUM(D21:O21) -> 19411.873
B22: Maintenance | D22: 250 | E22: 250 | F22: 250 | G22: 250 | H22: 250 | I22: 250 | J22: 250 | K22: 250 | L22: 250 | M22: 250 | N22: 250 | O22: 250 | P22: =SUM(D22:O22) -> 3000
B23: Marketing | D23: 1000 | E23: 1000 | F23: 1000 | G23: 1000 | H23: 1000 | I23: 1000 | J23: 1000 | K23: 1000 | L23: 1000 | M23: 1000 | N23: 1000 | O23: 1000 | P23: =SUM(D23:O23) -> 12000
B24: Other Operating | D24: 250 | E24: 250 | F24: 250 | G24: 250 | H24: 250 | I24: 250 | J24: 250 | K24: 250 | L24: 250 | M24: 250 | N24: 250 | O24: 250 | P24: =SUM(D24:O24) -> 3000
B25: Loan Repayments | D25: =PMT(($C$44/12),$C$45,-$C$43,,0) -> 5150.8328 | E25: =PMT(($C$44/12),$C$45,-$C$43,,0) -> 5150.8328 | F25: =PMT(($C$44/12),$C$45,-$C$43,,0) -> 5150.8328 | G25: =PMT(($C$44/12),$C$45,-$C$43,,0) -> 5150.8328 | H25: =PMT(($C$44/12),$C$45,-$C$43,,0) -> 5150.8328 | I25: =PMT(($C$44/12),$C$45,-$C$43,,0) -> 5150.8328 | J25: =PMT(($C$44/12),$C$45,-$C$43,,0) -> 5150.8328 | K25: =PMT(($C$44/12),$C$45,-$C$43,,0) -> 5150.8328 | ... O25: =PMT(($C$44/12),$C$45,-$C$43,,0) -> 5150.8328 | P25: =SUM(D25:O25) -> 61809.994
B27: Total Expenses | D27: =SUM(D17:D25) -> 139492.11 | E27: =SUM(E17:E25) -> 149556.28 | F27: =SUM(F17:F25) -> 149162.29 | G27: =SUM(G17:G25) -> 152832.83 | H27: =SUM(H17:H25) -> 154389.91 | I27: =SUM(I17:I25) -> 142707.3 | J27: =SUM(J17:J25) -> 152842.05 | K27: =SUM(K17:K25) -> 155698.3 | ... P27: =SUM(P17:P25) -> 1811463
B29: Net Income | D29: =D14-D27 -> -13942.109 | E29: =E14-E27 -> 7381.2225 | F29: =F14-F27 -> 6762.7124 | G29: =G14-G27 -> 14567.167 | H29: =H14-H27 -> 17735.093 | I29: =I14-I27 -> -6694.7979 | J29: =J14-J27 -> 14557.947 | K29: =K14-K27 -> 20476.701 | ... P29: =P14-P27 -> 125719.51
B31: Assumptions: | D31: Notes:
B32: Number of trading days | C32: =SUM(D6:O6) -> 366 | D32: Open every day of the year
B33: Opening hours | C33: 12 | D33: 12 hours a day
B34: Seats at restaurant | C34: 50 | D34: *Note - this is pre social distancing regulations
B35: Sittings per day | C35: 3 | D35: 1 lunch, 2 dinner per table
B37: Average Food Price | C37: 30
B38: Average Drink Price | C38: 15
B39: Average cost of food supplies | C39: 0.3
B40: Average cost of beverage supplies | C40: 0.35
B41: Rent | C41: =2000*100 -> 200000 | D41: 100sqm restaurant space * $2000 per sqm per annum
B43: Bank loan for initial fit-out | C43: 850000
B44: Interest rate | C44: 0.04
B45: Loan term | C45: =20*12 -> 240 | D45: months
B47: Wage Expense * | C47: For simplicity we have kept the roster constant in all months - wages will act as a fixed cost in this example
B48: Staff Member | C48: Number of staff | D48: Total Hrs: | E48: Rate | F48: Expense per month | H48: Per Year
B49: Head Chef (Full Time) | C49: 1 | F49: =H49*C49/12 -> 7083.3333 | H49: 85000
B50: Chef (Full Time) | C50: 2 | F50: =H50*C50/12 -> 11666.667 | H50: 70000
...

Sheet Q2. Utilities Regression
B1: Y | C1: X
B2: Monthly Total Utilities | C2: Number of Customers
B3: 1517.1099 | C3: 2790
B4: 1641.903 | C4: 3487.5
B5: 1568.5382 | C5: 3465
B6: 1605.3332 | C6: 3720
B7: 1666.1579 | C7: 3825
B8: 1419.1735 | C8: 3022.5
B9: 1614.5533 | C9: 3720
B10: 1692.0491 | C10: 3915
B11: 1730.4308 | C11: 4045.5
B12: 1646.0446 | C12: 3735
B13: 1697.1746 | C13: 3813
B14: 1613.4047 | C14: 3510
B16: SUMMARY OUTPUT
B18: Regression Statistics
B19: Multiple R | C19: 0.8845446
B20: R Square | C20: 0.78241914
B21: Adjusted R Square | C21: 0.76066106
B22: Standard Error | C22: 41.830152
B23: Observations | C23: 12
B25: ANOVA
C26: df | D26: SS | E26: MS | F26: F | G26: Significance F
B27: Regression | C27: 1 | D27: 62921.296 | E27: 62921.296 | F27: 35.959925 | G27: 0.00013269877
B28: Residual | C28: 10 | D28: 17497.616 | E28: 1749.7616
B29: Total | C29: 11 | D29: 80418.912
C31: Coefficients | D31: Standard Error | E31: t Stat | F31: P-value | G31: Lower 95% | H31: Upper 95% | I31: Lower 95.0% | J31: Upper 95.0%
B32: Intercept | C32: 874.80292 | D32: 124.46497 | E32: 7.0285069 | F32: 3.5901864e-05 | G32: 597.47768 | H32: 1152.1282 | I32: 597.47768 | J32: 1152.1282
B33: Number of Customers | C33: 0.20707429 | D33: 0.034531608 | E33: 5.9966595 | F33: 0.00013269877 | G33: 0.13013308 | H33: 0.28401551 | I33: 0.13013308 | J33: 0.28401551

Sheet Q3. Break-Even Analysis
A1: Average Food Price | B1: 30
A2: Average Drink Price | B2: 15
A3: Average cost of food supplies | B3: 0.3
A4: Average cost of beverage supplies | B4: 0.35
A7: CM | B7: =(B1+B2)-((B3*B1)+(B2*B4)) -> 30.75
A9: Rent | B9: 16666.667
A10: Wages* | B10: 74900
A11: Maintenance | B11: 250
A12: Marketing | B12: 1000
A13: Other Operating | B13: 250
A14: Loan Repayments | B14: 5150.8328
A15: Fixed Costs per month | B15: =SUM(B9:B14) -> 98217.499
A16: Utilities for this Year | B16: 19411.873
A17: Fixed cost for this year | B17: =(B15*12)+B16 -> 1198021.9
A18: Number of customers - Break Even | B18: =B17/B7 -> 38960.061
A19: Rounding up because you cannot have a fraction of a customer | B19: =ROUNDUP(B18,0) -> 38961

Sheet Q4. Target Profit
A1: Average Food Price | B1: 30
A2: Average Drink Price | B2: 15
A3: Average cost of food supplies | B3: 0.3
A4: Average cost of beverage supplies | B4: 0.35
A7: CM | B7: =(B1+B2)-((B3*B1)+(B2*B4)) -> 30.75
A9: Rent | B9: 16666.667
A10: Wages* | B10: 74900
A11: Maintenance | B11: 250
A12: Marketing | B12: 1000
A13: Other Operating | B13: 250
A14: Loan Repayments | B14: 5150.8328
A15: Fixed Costs per month | B15: =SUM(B9:B14) -> 98217.499
A16: Utilities for this Year | B16: 19411.873
A17: Fixed cost for this year | B17: =(B15*12)+B16 -> 1198021.9
A19: From the Question
A20: Profit per year | B20: 150000
A22: Quantity | B22: =(B20+B17)/B7 -> 43838.109
A23: Rounding up because you cannot have a fraction of a customer | B23: =ROUNDUP(B22,0) -> 43839
A26: Assumptions: | C26: Notes:
A27: Number of trading days | B27: 366 | C27: Open every day of the year
A28: Opening hours | B28: 12 | C28: 12 hours a day
A29: Seats at restaurant | B29: 50 | C29: *Note - this is pre social distancing regulations
A30: Sittings per day | B30: 3 | C30: 1 lunch, 2 dinner per table
A32: Total Seating Capacity per day | B32: =B29*B30 -> 150
A33: Total Seating Capacity per year | B33: =B32*B27 -> 54900
A34: Target Customers to be served | B34: =B23 -> 43839
A35: Percentage of capacity required to meet the target | B35: =B34/B33 -> 0.79852459

Sheet Updated Budget
B1: Restaurant Monthly Cash Budget
C3: Month | D3: July | E3: August | F3: September | G3: October | H3: November | I3: December | J3: January | K3: February | L3: March | M3: April | N3: May | O3: June | P3: Year | Q3: Q3 | R3: Q4
C4: Period start date | D4: 43647 | E4: 43678 | F4: 43709 | G4: 43739 | H4: 43770 | I4: 43800 | J4: 43831 | K4: 43862 | L4: 43891 | M4: 43922 | N4: 43952 | O4: 43983 | P4: =D4 -> 43647 | Q4: =J4 -> 43831 | R4: =M4 -> 43922
C5: Period end date | D5: 43677 | E5: 43708 | F5: 43738 | G5: 43769 | H5: 43799 | I5: 43830 | J5: 43861 | K5: 43890 | L5: 43921 | M5: 43951 | N5: 43982 | O5: 44012 | P5: =O5 -> 44012 | Q5: =L5 -> 43921 | R5: =O5 -> 44012
C6: Days in month | D6: =_xlfn.DAYS(D5,D4)+1 -> 31 | E6: =_xlfn.DAYS(E5,E4)+1 -> 31 | F6: =_xlfn.DAYS(F5,F4)+1 -> 30 | G6: =_xlfn.DAYS(G5,G4)+1 -> 31 | H6: =_xlfn.DAYS(H5,H4)+1 -> 30 | I6: =_xlfn.DAYS(I5,I4)+1 -> 31 | J6: =_xlfn.DAYS(J5,J4)+1 -> 31 | K6: =_xlfn.DAYS(K5,K4)+1 -> 29 | ... R6: =_xlfn.DAYS(R5,R4)+1 -> 91
B9: Revenue
B10: Forecast restaurant capacity utilization | D10: 0.6 | E10: 0.75 | F10: 0.77 | G10: 0.8 | H10: 0.85 | I10: 0.65 | J10: 0.8 | K10: 0.9 | L10: 0.87 | M10: 0.83 | N10: 0.82 | O10: 0.78 | P10: =AVERAGE(D10:O10) -> 0.785 | Q10: =AVERAGE(J10:L10) -> 0.85666667 | R10: =AVERAGE(M10:O10) -> 0.81 | S10: Do not adjust the capacity forecast.
B11: Customers | D11: 2790 | E11: 3487.5 | F11: 3465 | G11: 3720 | H11: 3825 | I11: 3022.5 | J11: 3720 | K11: 3915 | L11: 4045.5 | M11: =M6*$C$34*M10*$C$35 -> 1867.5 | N11: =N6*$C$34*N10*$C$35 -> 1906.5 | O11: =O6*$C$34*O10*$C$35 -> 1755 | P11: =SUM(D11:O11) -> 37519.5 | Q11: =SUM(J11:L11) -> 11680.5 | R11: =SUM(M11:O11) -> 5529
B12: Food | D12: 83700 | E12: 104625 | F12: 103950 | G12: 111600 | H12: 114750 | I12: 90675 | J12: 111600 | K12: 117450 | L12: 121365 | M12: =M11*$C$37 -> 56025 | N12: =N11*$C$37 -> 57195 | O12: =O11*$C$37 -> 52650 | P12: =SUM(D12:O12) -> 1125585 | Q12: =SUM(J12:L12) -> 350415 | R12: =SUM(M12:O12) -> 165870
B13: Beverages | D13: 41850 | E13: 52312.5 | F13: 51975 | G13: 55800 | H13: 57375 | I13: 45337.5 | J13: 55800 | K13: 58725 | L13: 60682.5 | M13: =M11*$C$38 -> 28012.5 | N13: =N11*$C$38 -> 28597.5 | O13: =O11*$C$38 -> 26325 | P13: =SUM(D13:O13) -> 562792.5 | Q13: =SUM(J13:L13) -> 175207.5 | R13: =SUM(M13:O13) -> 82935
B14: Total Revenue | D14: 125550 | E14: 156937.5 | F14: 155925 | G14: 167400 | H14: 172125 | I14: 136012.5 | J14: 167400 | K14: 176175 | L14: 182047.5 | M14: =SUM(M12:M13) -> 84037.5 | N14: =SUM(N12:N13) -> 85792.5 | O14: =SUM(O12:O13) -> 78975 | P14: =SUM(P12:P13) -> 1688377.5 | Q14: =SUM(J14:L14) -> 525622.5 | R14: =SUM(M14:O14) -> 248805
B16: Expenses
B17: Food Supplies | D17: 25110 | E17: 31387.5 | F17: 31185 | G17: 33480 | H17: 34425 | I17: 27202.5 | J17: 33480 | K17: 35235 | L17: 36409.5 | M17: =M12*$C$39 -> 16807.5 | N17: =N12*$C$39 -> 17158.5 | O17: =O12*$C$39 -> 15795 | P17: =SUM(D17:O17) -> 337675.5 | Q17: =SUM(J17:L17) -> 105124.5 | R17: =SUM(M17:O17) -> 49761
B18: Beverage Supplies | D18: 14647.5 | E18: 18309.375 | F18: 18191.25 | G18: 19530 | H18: 20081.25 | I18: 15868.125 | J18: 19530 | K18: 20553.75 | L18: 21238.875 | M18: =M13*$C$40 -> 9804.375 | N18: =N13*$C$40 -> 10009.125 | O18: =O13*$C$40 -> 9213.75 | P18: =SUM(D18:O18) -> 196977.38 | Q18: =SUM(J18:L18) -> 61322.625 | R18: =SUM(M18:O18) -> 29027.25
B19: Rent | D19: 16666.667 | E19: 16666.667 | F19: 16666.667 | G19: 16666.667 | H19: 16666.667 | I19: 16666.667 | J19: 16666.667 | K19: 16666.667 | L19: 16666.667 | M19: =$C$41/12 -> 16666.667 | N19: =$C$41/12 -> 16666.667 | O19: =$C$41/12 -> 16666.667 | P19: =SUM(D19:O19) -> 200000 | Q19: =SUM(J19:L19) -> 50000 | R19: =SUM(M19:O19) -> 50000
B20: Wages* | D20: 74900 | E20: 74900 | F20: 74900 | G20: 74900 | H20: 74900 | I20: 74900 | J20: 74900 | K20: 74900 | L20: 74900 | M20: =SUM(F49:G52) -> 41710 | N20: =SUM(F49:G52) -> 41710 | O20: =SUM(F49:G52) -> 41710 | P20: =SUM(D20:O20) -> 799230 | Q20: =SUM(J20:L20) -> 224700 | R20: =SUM(M20:O20) -> 125130
B21: Utilities | D21: 1517.1099 | E21: 1641.903 | F21: 1568.5382 | G21: 1605.3332 | H21: 1666.1579 | I21: 1419.1735 | J21: 1614.5533 | K21: 1692.0491 | L21: 1730.4308 | M21: ='Q2. Utilities Regression'!$C$32 + ('Q2. Utilities Regression'!$C$33*'Updated Budget'!M11) -> 1261.5142 | N21: ='Q2. Utilities Regression'!$C$32 + ('Q2. Utilities Regression'!$C$33*'Updated Budget'!N11) -> 1269.5901 | O21: ='Q2. Utilities Regression'!$C$32 + ('Q2. Utilities Regression'!$C$33*'Updated Budget'!O11) -> 1238.2183 | P21: =SUM(D21:O21) -> 18224.571 | Q21: =SUM(J21:L21) -> 5037.0332 | R21: =SUM(M21:O21) -> 3769.3225
B22: Maintenance | D22: 250 | E22: 250 | F22: 250 | G22: 250 | H22: 250 | I22: 250 | J22: 250 | K22: 250 | L22: 250 | M22: 250 | N22: 250 | O22: 250 | P22: =SUM(D22:O22) -> 3000 | Q22: =SUM(J22:L22) -> 750 | R22: =SUM(M22:O22) -> 750
B23: Marketing | D23: 1000 | E23: 1000 | F23: 1000 | G23: 1000 | H23: 1000 | I23: 1000 | J23: 1000 | K23: 1000 | L23: 1000 | M23: 1000 | N23: 1000 | O23: 1000 | P23: =SUM(D23:O23) -> 12000 | Q23: =SUM(J23:L23) -> 3000 | R23: =SUM(M23:O23) -> 3000
B24: Other Operating | D24: 250 | E24: 250 | F24: 250 | G24: 250 | H24: 250 | I24: 250 | J24: 250 | K24: 250 | L24: 250 | M24: 250 | N24: 250 | O24: 250 | P24: =SUM(D24:O24) -> 3000 | Q24: =SUM(J24:L24) -> 750 | R24: =SUM(M24:O24) -> 750
B25: Loan repayments | D25: 5150.8328 | E25: 5150.8328 | F25: 5150.8328 | G25: 5150.8328 | H25: 5150.8328 | I25: 5150.8328 | J25: 5150.8328 | K25: 5150.8328 | L25: 5150.8328 | M25: =PMT(($C$44/12),$C$45,-$C$43,,0) -> 4714.0796 | N25: =PMT(($C$44/12),$C$45,-$C$43,,0) -> 4714.0796 | O25: =PMT(($C$44/12),$C$45,-$C$43,,0) -> 4714.0796 | P25: =SUM(D25:O25) -> 60499.734 | Q25: =SUM(J25:L25) -> 15452.498 | R25: =SUM(M25:O25) -> 14142.239
B27: Total Expenses | D27: 139492.11 | E27: 149556.28 | F27: 149162.29 | G27: 152832.83 | H27: 154389.91 | I27: 142707.3 | J27: 152842.05 | K27: 155698.3 | L27: 157596.31 | M27: =SUM(M17:M25) -> 92464.135 | N27: =SUM(N17:N25) -> 93027.961 | O27: =SUM(O17:O25) -> 90837.715 | P27: =SUM(P17:P25) -> 1630607.2 | Q27: =SUM(J27:L27) -> 466136.66 | R27: =SUM(M27:O27) -> 276329.81
B29: Net Income | D29: =D14-D27 -> -13942.109 | E29: =E14-E27 -> 7381.2225 | F29: =F14-F27 -> 6762.7124 | G29: =G14-G27 -> 14567.167 | H29: =H14-H27 -> 17735.093 | I29: =I14-I27 -> -6694.7979 | J29: =J14-J27 -> 14557.947 | K29: =K14-K27 -> 20476.701 | ... R29: =R14-R27 -> -27524.811
B31: Assumptions: | D31: Notes: | O31: PM | P31: =P29/P14 -> 0.034216471 | Q31: =Q29/Q14 -> 0.11317218 | R31: =R29/R14 -> -0.11062805
B32: Number of trading days | C32: =SUM(D6:O6) -> 366 | D32: Open every day of the year
B33: Opening hours | C33: 12 | D33: 12 hours a day
B34: Seats at restaurant | C34: 25 | D34: *Note - this is after social distancing regulations
B35: Sittings per day | C35: 3 | D35: 1 lunch, 2 dinner per table
B37: Average Food Price | C37: 30
B38: Average Drink Price | C38: 15
B39: Average cost of food supplies | C39: 0.3
B40: Average cost of beverage supplies | C40: 0.35
B41: Rent | C41: =2000*100 -> 200000 | D41: $2000 per sqm per annum
B43: Bank loan for initial fit-out | C43: 850000
B44: Interest rate | C44: 0.03
B45: Loan term | C45: =20*12 -> 240 | D45: months
B47: Wage Expense * | C47: For simplicity we have kept the roster constant in all months - wages will act as a fixed cost in this example
B48: Staff Member | C48: Number of staff | D48: Total Hrs: | E48: Rate | F48: Expense per month | H48: Per Year
B49: Head Chef (Full Time) | C49: 1 | F49: =H49*C49/12 -> 7083.3333 | H49: 85000
B50: Chef (Full Time) | C50: 2 | F50: =H50*C50/12 -> 11666.667 | H50: 70000
...

Sheet Q8. Break Even Analysis-II
A1: Average Food Price | B1: 30
A2: Average Drink Price | B2: 15
A3: Average cost of food supplies | B3: 0.3
A4: Average cost of beverage supplies | B4: 0.35
A7: CM | B7: =(B1+B2)-((B3*B1)+(B2*B4)) -> 30.75
A9: Rent | B9: 50000
A10: Wages* | B10: 125130
A11: Utilities | B11: 3769.3225
A12: Maintenance | B12: 750
A13: Marketing | B13: 3000
A14: Other Operating | B14: 750
A15: Loan repayments | B15: 14142.239
A16: Fixed cost for this Quarter | B16: =SUM(B9:B15) -> 197541.56
A17: Number of customers - Break Even | B17: =B16/B7 -> 6424.1158
A18: Rounding up because you cannot have a fraction of a customer | B18: =ROUNDUP(B17,0) -> 6425

Sheet Q9. Target Profit - II
A1: Average Food Price | B1: 30
A2: Average Drink Price | B2: 15
A3: Average cost of food supplies | B3: 0.3
A4: Average cost of beverage supplies | B4: 0.35
A7: CM | B7: =(B1+B2)-((B3*B1)+(B2*B4)) -> 30.75
A9: Rent | B9: 50000
A10: Wages* | B10: 125130
A11: Utilities | B11: 3769.3225
A12: Maintenance | B12: 750
A13: Marketing | B13: 3000
A14: Other Operating | B14: 750
A15: Loan repayments | B15: 14142.239
A16: Fixed cost for this Quarter | B16: =SUM(B9:B15) -> 197541.56
A19: From the Question | F19: From the Question
A20: Profit per quarter | B20: 37500 | F20: Profit per quarter | G20: 12500
A22: Quantity | B22: =(B20+B16)/B7 -> 7643.628 | F22: Quantity | G22: 6830.6199
A23: Rounding up because you cannot have a fraction of a customer | B23: =ROUNDUP(B22,0) -> 7644 | F23: Rounding up because you cannot have a fraction of a customer | G23: 6831
A26: Assumptions: | C26: Notes: | F26: Assumptions:
A27: Number of trading days | B27: 91 | C27: Open every day of the year | F27: Number of trading days | G27: 91
A28: Opening hours | B28: 12 | C28: 12 hours a day | F28: Opening hours | G28: 12
A29: Seats at restaurant | B29: 25 | F29: Seats at restaurant | G29: 25
A30: Sittings per day | B30: 3 | C30: 1 lunch, 2 dinner per table | F30: Sittings per day | G30: 3
A32: Total Seating Capacity per day | B32: =B29*B30 -> 75 | F32: Total Seating Capacity per day | G32: 75
A33: Total Seating Capacity per Quarter | B33: =B32*B27 -> 6825 | F33: Total Seating Capacity per Quarter | G33: 6825
A34: Target Customers to be served | B34: =B23 -> 7644 | F34: Target Customers to be served | G34: 6831
A35: Percentage of capacity required to meet the target | B35: =B34/B33 -> 1.12 | F35: Percentage of capacity required to meet the target | G35: 1.0008791

Sheet Q10. Special Consideration
A1: Average Food Price | B1: 30
A2: Average Drink Price | B2: 15
A3: Average cost of food supplies | B3: 0.3
A4: Average cost of beverage supplies | B4: 0.35
A5: Cost of Food | B5: =B3*B1 -> 9
A6: Cost of Drink | B6: =B2*B4 -> 5.25
A8: Expected revenue without discount for lunch siting for 25 people | B8: =(B1+B2)*25 -> 1125
A10: April
A11: Customer | B11: =25*83% -> 20.75
A12: Revenue | B12: =B11*45*30 -> 28012.5
A13: revenue for one lunch sitting | B13: =B11*45 -> 933.75
A14: May
A15: Customer | B15: =25*82% -> 20.5
A16: Revenue | B16: =B15*45*31 -> 28597.5
A17: revenue for one lunch sitting | B17: =B15*45 -> 922.5
A18: June
A19: Customer | B19: =25*78% -> 19.5
A20: Revenue | B20: =B19*45*30 -> 26325
A21: revenue for one lunch sitting | B21: =B19*45 -> 877.5
A22: Total Revenue without deal | B22: =B20+B16+B12 -> 82935
A23: Total Revenue without deal for 3 lunch sittings | B23: =B21+B17+B13 -> 2733.75
A24: Discounted Food Price | B24: =B1-0.2*B1 -> 24
A25: Discounted Drink Price | B25: =B2-B2*0.2 -> 12
A27: Total Revenue per customer with discount | B27: =B24+B25 -> 36
A29: Total lunch revenue per sitting | B29: =B27*25 -> 900
A31: Lunch sitting revenue over three months | B31: =3*B29 -> 2700

Sheet Q11. Outsourcing Analysis
B1: 150 | C1: 0.3
A2: Orders | B2: Cost of Delivery (Delivery Driver) | C2: Cost of Delivery (UberEATS)
A3: 1 | B3: =$B$1/A3 -> 150 | C3: =('Q10. Special Consideration'!$B$1+'Q10. Special Consideration'!$B$2)*'Q11. Outsourcing Analysis'!$C$1 -> 13.5
A4: 2 | B4: =$B$1/A4 -> 75 | C4: =('Q10. Special Consideration'!$B$1+'Q10. Special Consideration'!$B$2)*'Q11. Outsourcing Analysis'!$C$1 -> 13.5
A5: 3 | B5: =$B$1/A5 -> 50 | C5: =('Q10. Special Consideration'!$B$1+'Q10. Special Consideration'!$B$2)*'Q11. Outsourcing Analysis'!$C$1 -> 13.5
A6: 4 | B6: =$B$1/A6 -> 37.5 | C6: =('Q10. Special Consideration'!$B$1+'Q10. Special Consideration'!$B$2)*'Q11. Outsourcing Analysis'!$C$1 -> 13.5
A7: 5 | B7: =$B$1/A7 -> 30 | C7: =('Q10. Special Consideration'!$B$1+'Q10. Special Consideration'!$B$2)*'Q11. Outsourcing Analysis'!$C$1 -> 13.5
A8: 6 | B8: =$B$1/A8 -> 25 | C8: =('Q10. Special Consideration'!$B$1+'Q10. Special Consideration'!$B$2)*'Q11. Outsourcing Analysis'!$C$1 -> 13.5
A9: 7 | B9: =$B$1/A9 -> 21.428571 | C9: =('Q10. Special Consideration'!$B$1+'Q10. Special Consideration'!$B$2)*'Q11. Outsourcing Analysis'!$C$1 -> 13.5
A10: 8 | B10: =$B$1/A10 -> 18.75 | C10: =('Q10. Special Consideration'!$B$1+'Q10. Special Consideration'!$B$2)*'Q11. Outsourcing Analysis'!$C$1 -> 13.5
A11: 9 | B11: =$B$1/A11 -> 16.666667 | C11: =('Q10. Special Consideration'!$B$1+'Q10. Special Consideration'!$B$2)*'Q11. Outsourcing Analysis'!$C$1 -> 13.5
A12: 10 | B12: =$B$1/A12 -> 15 | C12: =('Q10. Special Consideration'!$B$1+'Q10. Special Consideration'!$B$2)*'Q11. Outsourcing Analysis'!$C$1 -> 13.5
A13: 11 | B13: =$B$1/A13 -> 13.636364 | C13: =('Q10. Special Consideration'!$B$1+'Q10. Special Consideration'!$B$2)*'Q11. Outsourcing Analysis'!$C$1 -> 13.5
A14: 12 | B14: =$B$1/A14 -> 12.5 | C14: =('Q10. Special Consideration'!$B$1+'Q10. Special Consideration'!$B$2)*'Q11. Outsourcing Analysis'!$C$1 -> 13.5
... A42: 40 | B42: =$B$1/A42 -> 3.75 | C42: =('Q10. Special Consideration'!$B$1+'Q10. Special Consideration'!$B$2)*'Q11. Outsourcing Analysis'!$C$1 -> 13.5
